Workbook

Sheet Instrucciones
B2: Vídeotutoriales
B3: - En Teachable tenéis varios tutoriales con la resolución de los problemas más frecuentes que os soleis encontrar con la plantilla:
B4: - Solución problema frecuente: Separador decimal (ERROR "VALOR")
B5: - Uso de la plantilla desde Google Drive
B6: - Uso de plantilla con salidas a bolsas reciente (IPOs) o empresas con pocos años fiscales publicados
B8: Instrucciones de uso
B10: - Los datos "clave" que debes modificar manualmente para la valoración están marcados con números en NARANJA (Hojas 1, 2 y 4). También puedes modificar las celdas con fondo AZUL FLOJO, si así lo crees necesario.
B12: - Debes introducir todas las partidas con el MISMO SIGNO QUE EN TIKR (Número negativo = SALIDA DE CAJA. Número positivo = ENTRADA DE CAJA)
B14: - Opcional: Para que la plantilla obtenga los datos desde TIKR debes copiar cada uno de los estados financieros y pegarlos en la celda A1 de las hojas 7 (IS), 8 (BS) y 9 (CF)
B16: - OJO: Solo es válido para TIKR en INGLÉS, y es recomendable pegar los datos con "formato de destino"
B18: - Si no te aparece el botón "Copy table", debes seleccionar a mano los datos. Te sitúas con el cursor en la esquina izquierda superior de la tabla de TIKR y desde la franja negra "Income Statement | TIKR.com", arrastras hacia abajo para seleccionar todos los datos de la tabla. Después copias y pegas en la plantilla, como siempre.
B20: - Si no captura bien los datos, revisa que el separador decimal de tu aplicación de hoja de cálculo coincida con TIKR. También puedes probar a ocultar los decimales en TIKR ("Decimals to display" => 0) y pegar de nuevo los datos
... B26: - Hoja 4.Valoración: cálculo del market cap histórico actualizado para hacerlo compatible con cotizaciones de ADRs (NYSE:TSM, NYSE:NVO, OTC:LVMUY...)

Sheet 1.IS
B1: Income Statement | G1: =IF(TIKR_Cálculos!B85,TIKR_Cálculos!C85, IF(TIKR_Cálculos!B86,TIKR_Cálculos!C86, IF(TIKR_Cálculos!B87,TIKR_Cálculos!C87,""))) | O1: #VALUE!
A2: (millones, excepto EPS) | B2: =IFERROR(IF(VLOOKUP("Income Statement*",'7.TIKR_IS'!$A:$K,COLUMN(B3),FALSE)="","",IFERROR(YEAR(VLOOKUP("Income Statement*",'7.TIKR_IS'!$A:$K,COLUMN(B3),FALSE)),"2015")),"") | C2: =IFERROR(IF(VLOOKUP("Income Statement*",'7.TIKR_IS'!$A:$K,COLUMN(C3),FALSE)="","",IFERROR(YEAR(VLOOKUP("Income Statement*",'7.TIKR_IS'!$A:$K,COLUMN(C3),FALSE)),B2+1)),"") | D2: =IFERROR(IF(VLOOKUP("Income Statement*",'7.TIKR_IS'!$A:$K,COLUMN(D3),FALSE)="","",IFERROR(YEAR(VLOOKUP("Income Statement*",'7.TIKR_IS'!$A:$K,COLUMN(D3),FALSE)),C2+1)),"") | E2: =IFERROR(IF(VLOOKUP("Income Statement*",'7.TIKR_IS'!$A:$K,COLUMN(E3),FALSE)="","",IFERROR(YEAR(VLOOKUP("Income Statement*",'7.TIKR_IS'!$A:$K,COLUMN(E3),FALSE)),D2+1)),"") | F2: =IFERROR(IF(VLOOKUP("Income Statement*",'7.TIKR_IS'!$A:$K,COLUMN(F3),FALSE)="","",IFERROR(YEAR(VLOOKUP("Income Statement*",'7.TIKR_IS'!$A:$K,COLUMN(F3),FALSE)),E2+1)),"") | G2: =IFERROR(IF(VLOOKUP("Income Statement*",'7.TIKR_IS'!$A:$K,COLUMN(G3),FALSE)="","",IFERROR(YEAR(VLOOKUP("Income Statement*",'7.TIKR_IS'!$A:$K,COLUMN(G3),FALSE)),F2+1)),"") | H2: =IFERROR(IF(VLOOKUP("Income Statement*",'7.TIKR_IS'!$A:$K,COLUMN(H3),FALSE)="","",IFERROR(YEAR(VLOOKUP("Income Statement*",'7.TIKR_IS'!$A:$K,COLUMN(H3),FALSE)),G2+1)),"") | I2: =IFERROR(IF(VLOOKUP("Income Statement*",'7.TIKR_IS'!$A:$K,COLUMN(I3),FALSE)="","",IFERROR(YEAR(VLOOKUP("Income Statement*",'7.TIKR_IS'!$A:$K,COLUMN(I3),FALSE)),H2+1)),"") | J2: =IFERROR(IF(VLOOKUP("Income Statement*",'7.TIKR_IS'!$A:$K,COLUMN(J3),FALSE)="","",IFERROR(YEAR(VLOOKUP("Income Statement*",'7.TIKR_IS'!$A:$K,COLUMN(J3),FALSE)),I2+1)),"") | K2: =IFERROR(IF(VLOOKUP("Income Statement*",'7.TIKR_IS'!$A:$K,COLUMN(K3),FALSE)="","",IFERROR(YEAR(VLOOKUP("Income Statement*",'7.TIKR_IS'!$A:$K,COLUMN(K3),FALSE)),J2+1)),"") | L2: =IF(K2<>"",(K2+1)&"e","") | M2: =IF(L2<>"",(LEFT(L2,4)+1)&"e","") | N2: =IF(M2<>"",(LEFT(M2,4)+1)&"e","") | O2: =IF(N2<>"",(LEFT(N2,4)+1)&"e","") | P2: =IF(O2<>"",(LEFT(O2,4)+1)&"e","") | S2: {="CAGR "&CHAR(10)&INDEX(B2:K2,MATCH(TRUE,VALUE(B2:K2)>0,))&" - "&K2} -> #N/A
A3: Sales | B3: =IFERROR(VLOOKUP("Total Revenues*",'7.TIKR_IS'!$A:$K,COLUMN(B3),FALSE),"0") -> 0 | C3: =IFERROR(VLOOKUP("Total Revenues*",'7.TIKR_IS'!$A:$K,COLUMN(C3),FALSE),"0") -> 0 | D3: =IFERROR(VLOOKUP("Total Revenues*",'7.TIKR_IS'!$A:$K,COLUMN(D3),FALSE),"0") -> 0 | E3: =IFERROR(VLOOKUP("Total Revenues*",'7.TIKR_IS'!$A:$K,COLUMN(E3),FALSE),"0") -> 0 | F3: =IFERROR(VLOOKUP("Total Revenues*",'7.TIKR_IS'!$A:$K,COLUMN(F3),FALSE),"0") -> 0 | G3: =IFERROR(VLOOKUP("Total Revenues*",'7.TIKR_IS'!$A:$K,COLUMN(G3),FALSE),"0") -> 0 | H3: =IFERROR(VLOOKUP("Total Revenues*",'7.TIKR_IS'!$A:$K,COLUMN(H3),FALSE),"0") -> 0 | I3: =IFERROR(VLOOKUP("Total Revenues*",'7.TIKR_IS'!$A:$K,COLUMN(I3),FALSE),"0") -> 0 | ... K3: =IFERROR(VLOOKUP("Total Revenues*",'7.TIKR_IS'!$A:$K,COLUMN(K3),FALSE),"0") -> 0 | L3: =IFERROR(K3*(1+L4),"") | M3: =IFERROR(L3*(1+M4),"") | N3: =IFERROR(M3*(1+N4),"") | O3: =IFERROR(N3*(1+O4),"") | P3: =IFERROR(O3*(1+P4),"") | R3: Ventas | S3: {=IFERROR(('1.IS'!K3/INDEX(B3:K3,MATCH(TRUE,B3:K3>0,0)))^(1/10)-1,"-")} -> -
A4: Y/Y Growth % | C4: =IFERROR((C3-B3)/ABS(B3),"") | D4: =IFERROR((D3-C3)/ABS(C3),"") | E4: =IFERROR((E3-D3)/ABS(D3),"") | F4: =IFERROR((F3-E3)/ABS(E3),"") | G4: =IFERROR((G3-F3)/ABS(F3),"") | H4: =IFERROR((H3-G3)/ABS(G3),"") | I4: =IFERROR((I3-H3)/ABS(H3),"") | J4: =IFERROR((J3-I3)/ABS(I3),"") | K4: =IFERROR((K3-J3)/ABS(J3),"") | L4: =IFERROR(MEDIAN(I4:K4),IFERROR(IF(ISNUMBER(S3),S3,S11),0%)) | M4: =L4 | N4: =M4 | O4: =N4 | P4: =O4 | R4: EBITDA | S4: {=IFERROR(('1.IS'!K5/INDEX(B5:K5,MATCH(TRUE,B5:K5>0,0)))^(1/10)-1,"-")} -> -
A5: EBITDA | B5: =B9-B8 -> 0 | C5: =C9-C8 -> 0 | D5: =D9-D8 -> 0 | E5: =E9-E8 -> 0 | F5: =F9-F8 -> 0 | G5: =G9-G8 -> 0 | H5: =H9-H8 -> 0 | I5: =I9-I8 -> 0 | ... K5: =K9-K8 -> 0 | L5: =IFERROR(L9-L8,"") | M5: =IFERROR(M9-M8,"") | N5: =IFERROR(N9-N8,"") | O5: =IFERROR(O9-O8,"") | P5: =IFERROR(P9-P8,"") | R5: EBIT | S5: {=IFERROR(('1.IS'!K9/INDEX(B9:K9,MATCH(TRUE,B9:K9>0,0)))^(1/10)-1,"-")} -> -
A6: EBITDA margin % | B6: =IFERROR((B5/B3),"") | C6: =IFERROR((C5/C3),"") | D6: =IFERROR((D5/D3),"") | E6: =IFERROR((E5/E3),"") | F6: =IFERROR((F5/F3),"") | G6: =IFERROR((G5/G3),"") | H6: =IFERROR((H5/H3),"") | I6: =IFERROR((I5/I3),"") | ... K6: =IFERROR((K5/K3),"") | L6: =IFERROR(L5/L3,"") | M6: =IFERROR(M5/M3,"") | N6: =IFERROR(N5/N3,"") | O6: =IFERROR(O5/O3,"") | P6: =IFERROR(P5/P3,"") | R6: Beneficio Neto | S6: {=IFERROR(('1.IS'!K20/INDEX(B20:K20,MATCH(TRUE,B20:K20>0,0)))^(1/10)-1,"-")} -> -
A7: Y/Y Growth % | C7: =IFERROR((C5-B5)/ABS(B5),"") | D7: =IFERROR((D5-C5)/ABS(C5),"") | E7: =IFERROR((E5-D5)/ABS(D5),"") | F7: =IFERROR((F5-E5)/ABS(E5),"") | G7: =IFERROR((G5-F5)/ABS(F5),"") | H7: =IFERROR((H5-G5)/ABS(G5),"") | I7: =IFERROR((I5-H5)/ABS(H5),"") | J7: =IFERROR((J5-I5)/ABS(I5),"") | K7: =IFERROR((K5-J5)/ABS(J5),"") | L7: =IFERROR((L5-K5)/K5,"") | M7: =IFERROR((M5-L5)/L5,"") | N7: =IFERROR((N5-M5)/M5,"") | O7: =IFERROR((O5-N5)/N5,"") | P7: =IFERROR((P5-O5)/O5,"") | R7: EPS | S7: {=IFERROR(('1.IS'!K23/INDEX(B23:K23,MATCH(TRUE,B23:K23>0,0)))^(1/10)-1,"-")} -> -
A8: Depreciation & Amortization | B8: =IFERROR(-VLOOKUP("Depreciation*",'9.TIKR_CF'!$A:$K,COLUMN(B8),FALSE)-IFERROR(VLOOKUP("Amortization of Goodwill and Intangible Assets*",'9.TIKR_CF'!$A:$K,COLUMN(B8),FALSE),"0"),"0") -> 0 | C8: =IFERROR(-VLOOKUP("Depreciation*",'9.TIKR_CF'!$A:$K,COLUMN(C8),FALSE)-IFERROR(VLOOKUP("Amortization of Goodwill and Intangible Assets*",'9.TIKR_CF'!$A:$K,COLUMN(C8),FALSE),"0"),"0") -> 0 | D8: =IFERROR(-VLOOKUP("Depreciation*",'9.TIKR_CF'!$A:$K,COLUMN(D8),FALSE)-IFERROR(VLOOKUP("Amortization of Goodwill and Intangible Assets*",'9.TIKR_CF'!$A:$K,COLUMN(D8),FALSE),"0"),"0") -> 0 | E8: =IFERROR(-VLOOKUP("Depreciation*",'9.TIKR_CF'!$A:$K,COLUMN(E8),FALSE)-IFERROR(VLOOKUP("Amortization of Goodwill and Intangible Assets*",'9.TIKR_CF'!$A:$K,COLUMN(E8),FALSE),"0"),"0") -> 0 | F8: =IFERROR(-VLOOKUP("Depreciation*",'9.TIKR_CF'!$A:$K,COLUMN(F8),FALSE)-IFERROR(VLOOKUP("Amortization of Goodwill and Intangible Assets*",'9.TIKR_CF'!$A:$K,COLUMN(F8),FALSE),"0"),"0") -> 0 | G8: =IFERROR(-VLOOKUP("Depreciation*",'9.TIKR_CF'!$A:$K,COLUMN(G8),FALSE)-IFERROR(VLOOKUP("Amortization of Goodwill and Intangible Assets*",'9.TIKR_CF'!$A:$K,COLUMN(G8),FALSE),"0"),"0") -> 0 | H8: =IFERROR(-VLOOKUP("Depreciation*",'9.TIKR_CF'!$A:$K,COLUMN(H8),FALSE)-IFERROR(VLOOKUP("Amortization of Goodwill and Intangible Assets*",'9.TIKR_CF'!$A:$K,COLUMN(H8),FALSE),"0"),"0") -> 0 | I8: =IFERROR(-VLOOKUP("Depreciation*",'9.TIKR_CF'!$A:$K,COLUMN(I8),FALSE)-IFERROR(VLOOKUP("Amortization of Goodwill and Intangible Assets*",'9.TIKR_CF'!$A:$K,COLUMN(I8),FALSE),"0"),"0") -> 0 | ... K8: =IFERROR(-VLOOKUP("Depreciation*",'9.TIKR_CF'!$A:$K,COLUMN(K8),FALSE)-IFERROR(VLOOKUP("Amortization of Goodwill and Intangible Assets*",'9.TIKR_CF'!$A:$K,COLUMN(K8),FALSE),"0"),"0") -> 0 | L8: =IFERROR(K8*(1+L4),"") | M8: =IFERROR(L8*(1+M4),"") | N8: =IFERROR(M8*(1+N4),"") | O8: =IFERROR(N8*(1+O4),"") | P8: =IFERROR(O8*(1+P4),"")
A9: EBIT | B9: =IFERROR(VLOOKUP("Operating Income*",'7.TIKR_IS'!$A:$K,COLUMN(B2),FALSE),"0") -> 0 | C9: =IFERROR(VLOOKUP("Operating Income*",'7.TIKR_IS'!$A:$K,COLUMN(C2),FALSE),"0") -> 0 | D9: =IFERROR(VLOOKUP("Operating Income*",'7.TIKR_IS'!$A:$K,COLUMN(D2),FALSE),"0") -> 0 | E9: =IFERROR(VLOOKUP("Operating Income*",'7.TIKR_IS'!$A:$K,COLUMN(E2),FALSE),"0") -> 0 | F9: =IFERROR(VLOOKUP("Operating Income*",'7.TIKR_IS'!$A:$K,COLUMN(F2),FALSE),"0") -> 0 | G9: =IFERROR(VLOOKUP("Operating Income*",'7.TIKR_IS'!$A:$K,COLUMN(G2),FALSE),"0") -> 0 | H9: =IFERROR(VLOOKUP("Operating Income*",'7.TIKR_IS'!$A:$K,COLUMN(H2),FALSE),"0") -> 0 | I9: =IFERROR(VLOOKUP("Operating Income*",'7.TIKR_IS'!$A:$K,COLUMN(I2),FALSE),"0") -> 0 | ... K9: =IFERROR(VLOOKUP("Operating Income*",'7.TIKR_IS'!$A:$K,COLUMN(K2),FALSE),"0") -> 0 | L9: =IFERROR(L3*L10,"") | M9: =IFERROR(M3*M10,"") | N9: =IFERROR(N3*N10,"") | O9: =IFERROR(O3*O10,"") | P9: =IFERROR(P3*P10,"") | S9: {="Promedio "&CHAR(10)&INDEX(B2:K2,MATCH(TRUE,VALUE(B2:K2)>0,))&" - "&K2} -> #N/A
A10: EBIT margin % | B10: =IFERROR((B9/B3),"") | C10: =IFERROR((C9/C3),"") | D10: =IFERROR((D9/D3),"") | E10: =IFERROR((E9/E3),"") | F10: =IFERROR((F9/F3),"") | G10: =IFERROR((G9/G3),"") | H10: =IFERROR((H9/H3),"") | I10: =IFERROR((I9/I3),"") | ... K10: =IFERROR((K9/K3),"") | L10: =IFERROR(MEDIAN(I10:K10),S12) | M10: =L10 | N10: =M10 | O10: =N10 | P10: =O10
A11: Y/Y Growth % | C11: =IFERROR((C9-B9)/ABS(B9),"") | D11: =IFERROR((D9-C9)/ABS(C9),"") | E11: =IFERROR((E9-D9)/ABS(D9),"") | F11: =IFERROR((F9-E9)/ABS(E9),"") | G11: =IFERROR((G9-F9)/ABS(F9),"") | H11: =IFERROR((H9-G9)/ABS(G9),"") | I11: =IFERROR((I9-H9)/ABS(H9),"") | J11: =IFERROR((J9-I9)/ABS(I9),"") | K11: =IFERROR((K9-J9)/ABS(J9),"") | L11: =IFERROR((L9-K9)/K9,"") | M11: =IFERROR((M9-L9)/L9,"") | N11: =IFERROR((N9-M9)/M9,"") | O11: =IFERROR((O9-N9)/N9,"") | P11: =IFERROR((P9-O9)/O9,"") | R11: Crecimiento de Ventas | S11: =IFERROR(AVERAGE(C4:K4),"")
A12: Interest Expense | B12: =IFERROR(VLOOKUP("Interest Expense*",'7.TIKR_IS'!$A:$K,COLUMN(B12),FALSE),"0") -> 0 | C12: =IFERROR(VLOOKUP("Interest Expense*",'7.TIKR_IS'!$A:$K,COLUMN(C12),FALSE),"0") -> 0 | D12: =IFERROR(VLOOKUP("Interest Expense*",'7.TIKR_IS'!$A:$K,COLUMN(D12),FALSE),"0") -> 0 | E12: =IFERROR(VLOOKUP("Interest Expense*",'7.TIKR_IS'!$A:$K,COLUMN(E12),FALSE),"0") -> 0 | F12: =IFERROR(VLOOKUP("Interest Expense*",'7.TIKR_IS'!$A:$K,COLUMN(F12),FALSE),"0") -> 0 | G12: =IFERROR(VLOOKUP("Interest Expense*",'7.TIKR_IS'!$A:$K,COLUMN(G12),FALSE),"0") -> 0 | H12: =IFERROR(VLOOKUP("Interest Expense*",'7.TIKR_IS'!$A:$K,COLUMN(H12),FALSE),"0") -> 0 | I12: =IFERROR(VLOOKUP("Interest Expense*",'7.TIKR_IS'!$A:$K,COLUMN(I12),FALSE),"0") -> 0 | ... K12: =IFERROR(VLOOKUP("Interest Expense*",'7.TIKR_IS'!$A:$K,COLUMN(K12),FALSE),"0") -> 0 | L12: =IFERROR(-TIKR_Cálculos!$B$27*SUM('3.ROIC'!L6:L7),"") | M12: =IFERROR(-TIKR_Cálculos!$B$27*SUM('3.ROIC'!M6:M7),"") | N12: =IFERROR(-TIKR_Cálculos!$B$27*SUM('3.ROIC'!N6:N7),"") | O12: =IFERROR(-TIKR_Cálculos!$B$27*SUM('3.ROIC'!O6:O7),"") | P12: =IFERROR(-TIKR_Cálculos!$B$27*SUM('3.ROIC'!P6:P7),"") | R12: Margen EBIT | S12: =IFERROR(AVERAGE(B10:K10),"")
A13: Interest Income | B13: =IFERROR(VLOOKUP("Interest And Investment Income*",'7.TIKR_IS'!$A:$K,COLUMN(B13),FALSE),"0") -> 0 | C13: =IFERROR(VLOOKUP("Interest And Investment Income*",'7.TIKR_IS'!$A:$K,COLUMN(C13),FALSE),"0") -> 0 | D13: =IFERROR(VLOOKUP("Interest And Investment Income*",'7.TIKR_IS'!$A:$K,COLUMN(D13),FALSE),"0") -> 0 | E13: =IFERROR(VLOOKUP("Interest And Investment Income*",'7.TIKR_IS'!$A:$K,COLUMN(E13),FALSE),"0") -> 0 | F13: =IFERROR(VLOOKUP("Interest And Investment Income*",'7.TIKR_IS'!$A:$K,COLUMN(F13),FALSE),"0") -> 0 | G13: =IFERROR(VLOOKUP("Interest And Investment Income*",'7.TIKR_IS'!$A:$K,COLUMN(G13),FALSE),"0") -> 0 | H13: =IFERROR(VLOOKUP("Interest And Investment Income*",'7.TIKR_IS'!$A:$K,COLUMN(H13),FALSE),"0") -> 0 | I13: =IFERROR(VLOOKUP("Interest And Investment Income*",'7.TIKR_IS'!$A:$K,COLUMN(I13),FALSE),"0") -> 0 | ... K13: =IFERROR(VLOOKUP("Interest And Investment Income*",'7.TIKR_IS'!$A:$K,COLUMN(K13),FALSE),"0") -> 0 | L13: =IFERROR(TIKR_Cálculos!$B$26*'3.ROIC'!L5,"") -> 0 | M13: =IFERROR(TIKR_Cálculos!$B$26*'3.ROIC'!M5,"") -> 0 | N13: =IFERROR(TIKR_Cálculos!$B$26*'3.ROIC'!N5,"") -> 0 | O13: =IFERROR(TIKR_Cálculos!$B$26*'3.ROIC'!O5,"") -> 0 | P13: =IFERROR(TIKR_Cálculos!$B$26*'3.ROIC'!P5,"") -> 0 | R13: Tax Rate | S13: =IFERROR(AVERAGE(B17:K17),"")
A14: Total Interest expense | B14: =B12+B13 -> 0 | C14: =C12+C13 -> 0 | D14: =D12+D13 -> 0 | E14: =E12+E13 -> 0 | F14: =F12+F13 -> 0 | G14: =G12+G13 -> 0 | H14: =H12+H13 -> 0 | I14: =I12+I13 -> 0 | ... K14: =K12+K13 -> 0 | L14: =IFERROR(SUM(L12:L13),"") -> 0 | M14: =IFERROR(SUM(M12:M13),"") -> 0 | N14: =IFERROR(SUM(N12:N13),"") -> 0 | O14: =IFERROR(SUM(O12:O13),"") -> 0 | P14: =IFERROR(SUM(P12:P13),"") -> 0 | R14: Aumento nº acciones | S14: =IFERROR(AVERAGE(C26:K26),"")
A15: EBT | B15: =IFERROR(B9+B14,"") -> 0 | C15: =IFERROR(C9+C14,"") -> 0 | D15: =IFERROR(D9+D14,"") -> 0 | E15: =IFERROR(E9+E14,"") -> 0 | F15: =IFERROR(F9+F14,"") -> 0 | G15: =IFERROR(G9+G14,"") -> 0 | H15: =IFERROR(H9+H14,"") -> 0 | I15: =IFERROR(I9+I14,"") -> 0 | ... P15: =IFERROR(P9+P14,"")
A16: Tax Expense - en negativo | B16: =IFERROR(VLOOKUP("Income Tax Expense*",'7.TIKR_IS'!$A:$K,COLUMN(B16),FALSE),"0") -> 0 | C16: =IFERROR(VLOOKUP("Income Tax Expense*",'7.TIKR_IS'!$A:$K,COLUMN(C16),FALSE),"0") -> 0 | D16: =IFERROR(VLOOKUP("Income Tax Expense*",'7.TIKR_IS'!$A:$K,COLUMN(D16),FALSE),"0") -> 0 | E16: =IFERROR(VLOOKUP("Income Tax Expense*",'7.TIKR_IS'!$A:$K,COLUMN(E16),FALSE),"0") -> 0 | F16: =IFERROR(VLOOKUP("Income Tax Expense*",'7.TIKR_IS'!$A:$K,COLUMN(F16),FALSE),"0") -> 0 | G16: =IFERROR(VLOOKUP("Income Tax Expense*",'7.TIKR_IS'!$A:$K,COLUMN(G16),FALSE),"0") -> 0 | H16: =IFERROR(VLOOKUP("Income Tax Expense*",'7.TIKR_IS'!$A:$K,COLUMN(H16),FALSE),"0") -> 0 | I16: =IFERROR(VLOOKUP("Income Tax Expense*",'7.TIKR_IS'!$A:$K,COLUMN(I16),FALSE),"0") -> 0 | ... K16: =IFERROR(VLOOKUP("Income Tax Expense*",'7.TIKR_IS'!$A:$K,COLUMN(K16),FALSE),"0") -> 0 | L16: =IFERROR(-L15*L17,"") | M16: =IFERROR(-M15*M17,"") | N16: =IFERROR(-N15*N17,"") | O16: =IFERROR(-O15*O17,"") | P16: =IFERROR(-P15*P17,"") | R16: AJUSTAR MANUALMENTE
A17: Tax rate % | B17: =IFERROR((ABS(B16)/B15),"") | C17: =IFERROR((ABS(C16)/C15),"") | D17: =IFERROR((ABS(D16)/D15),"") | E17: =IFERROR((ABS(E16)/E15),"") | F17: =IFERROR((ABS(F16)/F15),"") | G17: =IFERROR((ABS(G16)/G15),"") | H17: =IFERROR((ABS(H16)/H15),"") | I17: =IFERROR((ABS(I16)/I15),"") | ... K17: =IFERROR((ABS(K16)/K15),"") | L17: =IFERROR(MEDIAN(I17:K17),S13) | M17: =L17 | N17: =M17 | O17: =N17 | P17: =O17
A18: Consolidated Net Income | B18: =B15+B16 -> 0 | C18: =C15+C16 -> 0 | D18: =D15+D16 -> 0 | E18: =E15+E16 -> 0 | F18: =F15+F16 -> 0 | G18: =G15+G16 -> 0 | H18: =H15+H16 -> 0 | I18: =I15+I16 -> 0 | ... K18: =K15+K16 -> 0 | L18: =IFERROR(L15+L16,"") | M18: =IFERROR(M15+M16,"") | N18: =IFERROR(N15+N16,"") | O18: =IFERROR(O15+O16,"") | P18: =IFERROR(P15+P16,"")
A19: Minority Interests | B19: =IFERROR(VLOOKUP("Minority Interest*",'7.TIKR_IS'!$A:$K,COLUMN(B19),FALSE),"0") -> 0 | C19: =IFERROR(VLOOKUP("Minority Interest*",'7.TIKR_IS'!$A:$K,COLUMN(C19),FALSE),"0") -> 0 | D19: =IFERROR(VLOOKUP("Minority Interest*",'7.TIKR_IS'!$A:$K,COLUMN(D19),FALSE),"0") -> 0 | E19: =IFERROR(VLOOKUP("Minority Interest*",'7.TIKR_IS'!$A:$K,COLUMN(E19),FALSE),"0") -> 0 | F19: =IFERROR(VLOOKUP("Minority Interest*",'7.TIKR_IS'!$A:$K,COLUMN(F19),FALSE),"0") -> 0 | G19: =IFERROR(VLOOKUP("Minority Interest*",'7.TIKR_IS'!$A:$K,COLUMN(G19),FALSE),"0") -> 0 | H19: =IFERROR(VLOOKUP("Minority Interest*",'7.TIKR_IS'!$A:$K,COLUMN(H19),FALSE),"0") -> 0 | I19: =IFERROR(VLOOKUP("Minority Interest*",'7.TIKR_IS'!$A:$K,COLUMN(I19),FALSE),"0") -> 0 | ... K19: =IFERROR(VLOOKUP("Minority Interest*",'7.TIKR_IS'!$A:$K,COLUMN(K19),FALSE),"0") -> 0 | L19: =IFERROR(K19/K18*L18,"") | M19: =IFERROR(L19/L18*M18,"") | N19: =IFERROR(M19/M18*N18,"") | O19: =IFERROR(N19/N18*O18,"") | P19: =IFERROR(O19/O18*P18,"")
A20: Net Income | B20: =B18+B19 -> 0 | C20: =C18+C19 -> 0 | D20: =D18+D19 -> 0 | E20: =E18+E19 -> 0 | F20: =F18+F19 -> 0 | G20: =G18+G19 -> 0 | H20: =H18+H19 -> 0 | I20: =I18+I19 -> 0 | ... K20: =K18+K19 -> 0 | L20: =IFERROR(L18+L19,"") | M20: =IFERROR(M18+M19,"") | N20: =IFERROR(N18+N19,"") | O20: =IFERROR(O18+O19,"") | P20: =IFERROR(P18+P19,"")
A21: Net margin % | B21: =IFERROR(B20/B3,"") | C21: =IFERROR(C20/C3,"") | D21: =IFERROR(D20/D3,"") | E21: =IFERROR(E20/E3,"") | F21: =IFERROR(F20/F3,"") | G21: =IFERROR(G20/G3,"") | H21: =IFERROR(H20/H3,"") | I21: =IFERROR(I20/I3,"") | ... P21: =IFERROR(P20/P3,"")
A22: Y/Y Growth % | C22: =IFERROR((C20-B20)/ABS(B20),"") | D22: =IFERROR((D20-C20)/ABS(C20),"") | E22: =IFERROR((E20-D20)/ABS(D20),"") | F22: =IFERROR((F20-E20)/ABS(E20),"") | G22: =IFERROR((G20-F20)/ABS(F20),"") | H22: =IFERROR((H20-G20)/ABS(G20),"") | I22: =IFERROR((I20-H20)/ABS(H20),"") | J22: =IFERROR((J20-I20)/ABS(I20),"") | K22: =IFERROR((K20-J20)/ABS(J20),"") | L22: =IFERROR((L20-K20)/K20,"") | M22: =IFERROR((M20-L20)/L20,"") | N22: =IFERROR((N20-M20)/M20,"") | O22: =IFERROR((O20-N20)/N20,"") | P22: =IFERROR((P20-O20)/O20,"")
A23: EPS | B23: =IFERROR(B20/B25,"") | C23: =IFERROR(C20/C25,"") | D23: =IFERROR(D20/D25,"") | E23: =IFERROR(E20/E25,"") | F23: =IFERROR(F20/F25,"") | G23: =IFERROR(G20/G25,"") | H23: =IFERROR(H20/H25,"") | I23: =IFERROR(I20/I25,"") | ... P23: =IFERROR(P20/P25,"")
A24: Y/Y Growth % | C24: =IFERROR((C23-B23)/ABS(B23),"") | D24: =IFERROR((D23-C23)/ABS(C23),"") | E24: =IFERROR((E23-D23)/ABS(D23),"") | F24: =IFERROR((F23-E23)/ABS(E23),"") | G24: =IFERROR((G23-F23)/ABS(F23),"") | H24: =IFERROR((H23-G23)/ABS(G23),"") | I24: =IFERROR((I23-H23)/ABS(H23),"") | J24: =IFERROR((J23-I23)/ABS(I23),"") | K24: =IFERROR((K23-J23)/ABS(J23),"") | L24: =IFERROR((L23-K23)/K23,"") | M24: =IFERROR((M23-L23)/L23,"") | N24: =IFERROR((N23-M23)/M23,"") | O24: =IFERROR((O23-N23)/N23,"") | P24: =IFERROR((P23-O23)/O23,"")
A25: Fully diluted shares - millones | B25: =IFERROR(VLOOKUP("*Diluted Shares Outstanding*",'7.TIKR_IS'!$A:$K,COLUMN(B25),FALSE),"0") -> 0 | C25: =IFERROR(VLOOKUP("*Diluted Shares Outstanding*",'7.TIKR_IS'!$A:$K,COLUMN(C25),FALSE),"0") -> 0 | D25: =IFERROR(VLOOKUP("*Diluted Shares Outstanding*",'7.TIKR_IS'!$A:$K,COLUMN(D25),FALSE),"0") -> 0 | E25: =IFERROR(VLOOKUP("*Diluted Shares Outstanding*",'7.TIKR_IS'!$A:$K,COLUMN(E25),FALSE),"0") -> 0 | F25: =IFERROR(VLOOKUP("*Diluted Shares Outstanding*",'7.TIKR_IS'!$A:$K,COLUMN(F25),FALSE),"0") -> 0 | G25: =IFERROR(VLOOKUP("*Diluted Shares Outstanding*",'7.TIKR_IS'!$A:$K,COLUMN(G25),FALSE),"0") -> 0 | H25: =IFERROR(VLOOKUP("*Diluted Shares Outstanding*",'7.TIKR_IS'!$A:$K,COLUMN(H25),FALSE),"0") -> 0 | I25: =IFERROR(VLOOKUP("*Diluted Shares Outstanding*",'7.TIKR_IS'!$A:$K,COLUMN(I25),FALSE),"0") -> 0 | ... K25: =IFERROR(VLOOKUP("*Diluted Shares Outstanding*",'7.TIKR_IS'!$A:$K,COLUMN(K25),FALSE),"0") -> 0 | L25: =IFERROR(K25*(1+L26),"") | M25: =IFERROR(L25*(1+M26),"") | N25: =IFERROR(M25*(1+N26),"") | O25: =IFERROR(N25*(1+O26),"") | P25: =IFERROR(O25*(1+P26),"")
A26: Y/Y Growth % | C26: =IFERROR((C25-B25)/ABS(B25),"") | D26: =IFERROR((D25-C25)/ABS(C25),"") | E26: =IFERROR((E25-D25)/ABS(D25),"") | F26: =IFERROR((F25-E25)/ABS(E25),"") | G26: =IFERROR((G25-F25)/ABS(F25),"") | H26: =IFERROR((H25-G25)/ABS(G25),"") | I26: =IFERROR((I25-H25)/ABS(H25),"") | J26: =IFERROR((J25-I25)/ABS(I25),"") | K26: =IFERROR((K25-J25)/ABS(J25),"") | L26: =IFERROR(MEDIAN(I26:K26),S14) | M26: =L26 | N26: =M26 | O26: =N26 | P26: =O26

Sheet 2.FCF
A1: =IF('1.IS'!A1<>"",'1.IS'!A1,"") | B1: Cash Flow Statement | O1: #VALUE!
A2: (millones, excepto FCF per share) | B2: ='1.IS'!B$2 | C2: ='1.IS'!C$2 | D2: ='1.IS'!D$2 | E2: ='1.IS'!E$2 | F2: ='1.IS'!F$2 | G2: ='1.IS'!G$2 | H2: ='1.IS'!H$2 | I2: ='1.IS'!I$2 | ... P2: ='1.IS'!P$2
A3: EBITDA | B3: ='1.IS'!B5 -> 0 | C3: ='1.IS'!C5 -> 0 | D3: ='1.IS'!D5 -> 0 | E3: ='1.IS'!E5 -> 0 | F3: ='1.IS'!F5 -> 0 | G3: ='1.IS'!G5 -> 0 | H3: ='1.IS'!H5 -> 0 | I3: ='1.IS'!I5 -> 0 | ... P3: ='1.IS'!P5
A4: (-) CapEx Mantenimiento - en negativo | B4: =IFERROR(VLOOKUP("CapEx Mantenimiento",TIKR_Cálculos!$A:$K,COLUMN(B4),FALSE),"0") -> 0 | C4: =IFERROR(VLOOKUP("CapEx Mantenimiento",TIKR_Cálculos!$A:$K,COLUMN(C4),FALSE),"0") -> 0 | D4: =IFERROR(VLOOKUP("CapEx Mantenimiento",TIKR_Cálculos!$A:$K,COLUMN(D4),FALSE),"0") -> 0 | E4: =IFERROR(VLOOKUP("CapEx Mantenimiento",TIKR_Cálculos!$A:$K,COLUMN(E4),FALSE),"0") -> 0 | F4: =IFERROR(VLOOKUP("CapEx Mantenimiento",TIKR_Cálculos!$A:$K,COLUMN(F4),FALSE),"0") -> 0 | G4: =IFERROR(VLOOKUP("CapEx Mantenimiento",TIKR_Cálculos!$A:$K,COLUMN(G4),FALSE),"0") -> 0 | H4: =IFERROR(VLOOKUP("CapEx Mantenimiento",TIKR_Cálculos!$A:$K,COLUMN(H4),FALSE),"0") -> 0 | I4: =IFERROR(VLOOKUP("CapEx Mantenimiento",TIKR_Cálculos!$A:$K,COLUMN(I4),FALSE),"0") -> 0 | ... K4: =IFERROR(VLOOKUP("CapEx Mantenimiento",TIKR_Cálculos!$A:$K,COLUMN(K4),FALSE),"0") -> 0 | L4: =IFERROR(-L22*'1.IS'!L3,"") | M4: =IFERROR(-M22*'1.IS'!M3,"") | N4: =IFERROR(-N22*'1.IS'!N3,"") | O4: =IFERROR(-O22*'1.IS'!O3,"") | P4: =IFERROR(-P22*'1.IS'!P3,"")
A5: (-) Total interest expense | B5: ='1.IS'!B14 -> 0 | C5: ='1.IS'!C14 -> 0 | D5: ='1.IS'!D14 -> 0 | E5: ='1.IS'!E14 -> 0 | F5: ='1.IS'!F14 -> 0 | G5: ='1.IS'!G14 -> 0 | H5: ='1.IS'!H14 -> 0 | I5: ='1.IS'!I14 -> 0 | ... P5: ='1.IS'!P14 -> 0
A6: (-) Taxes paid | B6: ='1.IS'!B16 -> 0 | C6: ='1.IS'!C16 -> 0 | D6: ='1.IS'!D16 -> 0 | E6: ='1.IS'!E16 -> 0 | F6: ='1.IS'!F16 -> 0 | G6: ='1.IS'!G16 -> 0 | H6: ='1.IS'!H16 -> 0 | I6: ='1.IS'!I16 -> 0 | ... P6: ='1.IS'!P16
A7: (+) Inventories | B7: =IFERROR(VLOOKUP("Inventory*",'8.TIKR_BS'!$A:$K,COLUMN(B7),FALSE),"0") -> 0 | C7: =IFERROR(VLOOKUP("Inventory*",'8.TIKR_BS'!$A:$K,COLUMN(C7),FALSE),"0") -> 0 | D7: =IFERROR(VLOOKUP("Inventory*",'8.TIKR_BS'!$A:$K,COLUMN(D7),FALSE),"0") -> 0 | E7: =IFERROR(VLOOKUP("Inventory*",'8.TIKR_BS'!$A:$K,COLUMN(E7),FALSE),"0") -> 0 | F7: =IFERROR(VLOOKUP("Inventory*",'8.TIKR_BS'!$A:$K,COLUMN(F7),FALSE),"0") -> 0 | G7: =IFERROR(VLOOKUP("Inventory*",'8.TIKR_BS'!$A:$K,COLUMN(G7),FALSE),"0") -> 0 | H7: =IFERROR(VLOOKUP("Inventory*",'8.TIKR_BS'!$A:$K,COLUMN(H7),FALSE),"0") -> 0 | I7: =IFERROR(VLOOKUP("Inventory*",'8.TIKR_BS'!$A:$K,COLUMN(I7),FALSE),"0") -> 0 | ... K7: =IFERROR(VLOOKUP("Inventory*",'8.TIKR_BS'!$A:$K,COLUMN(K7),FALSE),"0") -> 0
A8: (+) Accounts Receivable | B8: =IFERROR(VLOOKUP("Accounts Receivable*",'8.TIKR_BS'!$A:$K,COLUMN(B8),FALSE),"0") -> 0 | C8: =IFERROR(VLOOKUP("Accounts Receivable*",'8.TIKR_BS'!$A:$K,COLUMN(C8),FALSE),"0") -> 0 | D8: =IFERROR(VLOOKUP("Accounts Receivable*",'8.TIKR_BS'!$A:$K,COLUMN(D8),FALSE),"0") -> 0 | E8: =IFERROR(VLOOKUP("Accounts Receivable*",'8.TIKR_BS'!$A:$K,COLUMN(E8),FALSE),"0") -> 0 | F8: =IFERROR(VLOOKUP("Accounts Receivable*",'8.TIKR_BS'!$A:$K,COLUMN(F8),FALSE),"0") -> 0 | G8: =IFERROR(VLOOKUP("Accounts Receivable*",'8.TIKR_BS'!$A:$K,COLUMN(G8),FALSE),"0") -> 0 | H8: =IFERROR(VLOOKUP("Accounts Receivable*",'8.TIKR_BS'!$A:$K,COLUMN(H8),FALSE),"0") -> 0 | I8: =IFERROR(VLOOKUP("Accounts Receivable*",'8.TIKR_BS'!$A:$K,COLUMN(I8),FALSE),"0") -> 0 | ... K8: =IFERROR(VLOOKUP("Accounts Receivable*",'8.TIKR_BS'!$A:$K,COLUMN(K8),FALSE),"0") -> 0
A9: (-) Accounts Payable | B9: =IFERROR(VLOOKUP("Accounts Payable*",'8.TIKR_BS'!$A:$K,COLUMN(B9),FALSE),"0") -> 0 | C9: =IFERROR(VLOOKUP("Accounts Payable*",'8.TIKR_BS'!$A:$K,COLUMN(C9),FALSE),"0") -> 0 | D9: =IFERROR(VLOOKUP("Accounts Payable*",'8.TIKR_BS'!$A:$K,COLUMN(D9),FALSE),"0") -> 0 | E9: =IFERROR(VLOOKUP("Accounts Payable*",'8.TIKR_BS'!$A:$K,COLUMN(E9),FALSE),"0") -> 0 | F9: =IFERROR(VLOOKUP("Accounts Payable*",'8.TIKR_BS'!$A:$K,COLUMN(F9),FALSE),"0") -> 0 | G9: =IFERROR(VLOOKUP("Accounts Payable*",'8.TIKR_BS'!$A:$K,COLUMN(G9),FALSE),"0") -> 0 | H9: =IFERROR(VLOOKUP("Accounts Payable*",'8.TIKR_BS'!$A:$K,COLUMN(H9),FALSE),"0") -> 0 | I9: =IFERROR(VLOOKUP("Accounts Payable*",'8.TIKR_BS'!$A:$K,COLUMN(I9),FALSE),"0") -> 0 | ... K9: =IFERROR(VLOOKUP("Accounts Payable*",'8.TIKR_BS'!$A:$K,COLUMN(K9),FALSE),"0") -> 0
A10: (-) Unearned Revenue | B10: =IFERROR(VLOOKUP("Unearned Revenue Current*",'8.TIKR_BS'!$A:$K,COLUMN(B9),FALSE),"0")+IFERROR(VLOOKUP("Unearned Revenue Non Current*",'8.TIKR_BS'!$A:$K,COLUMN(B9),FALSE),"0") -> 0 | C10: =IFERROR(VLOOKUP("Unearned Revenue Current*",'8.TIKR_BS'!$A:$K,COLUMN(C9),FALSE),"0")+IFERROR(VLOOKUP("Unearned Revenue Non Current*",'8.TIKR_BS'!$A:$K,COLUMN(C9),FALSE),"0") -> 0 | D10: =IFERROR(VLOOKUP("Unearned Revenue Current*",'8.TIKR_BS'!$A:$K,COLUMN(D9),FALSE),"0")+IFERROR(VLOOKUP("Unearned Revenue Non Current*",'8.TIKR_BS'!$A:$K,COLUMN(D9),FALSE),"0") -> 0 | E10: =IFERROR(VLOOKUP("Unearned Revenue Current*",'8.TIKR_BS'!$A:$K,COLUMN(E9),FALSE),"0")+IFERROR(VLOOKUP("Unearned Revenue Non Current*",'8.TIKR_BS'!$A:$K,COLUMN(E9),FALSE),"0") -> 0 | F10: =IFERROR(VLOOKUP("Unearned Revenue Current*",'8.TIKR_BS'!$A:$K,COLUMN(F9),FALSE),"0")+IFERROR(VLOOKUP("Unearned Revenue Non Current*",'8.TIKR_BS'!$A:$K,COLUMN(F9),FALSE),"0") -> 0 | G10: =IFERROR(VLOOKUP("Unearned Revenue Current*",'8.TIKR_BS'!$A:$K,COLUMN(G9),FALSE),"0")+IFERROR(VLOOKUP("Unearned Revenue Non Current*",'8.TIKR_BS'!$A:$K,COLUMN(G9),FALSE),"0") -> 0 | H10: =IFERROR(VLOOKUP("Unearned Revenue Current*",'8.TIKR_BS'!$A:$K,COLUMN(H9),FALSE),"0")+IFERROR(VLOOKUP("Unearned Revenue Non Current*",'8.TIKR_BS'!$A:$K,COLUMN(H9),FALSE),"0") -> 0 | I10: =IFERROR(VLOOKUP("Unearned Revenue Current*",'8.TIKR_BS'!$A:$K,COLUMN(I9),FALSE),"0")+IFERROR(VLOOKUP("Unearned Revenue Non Current*",'8.TIKR_BS'!$A:$K,COLUMN(I9),FALSE),"0") -> 0 | ... K10: =IFERROR(VLOOKUP("Unearned Revenue Current*",'8.TIKR_BS'!$A:$K,COLUMN(K9),FALSE),"0")+IFERROR(VLOOKUP("Unearned Revenue Non Current*",'8.TIKR_BS'!$A:$K,COLUMN(K9),FALSE),"0") -> 0
A11: Working Capital - WC | B11: =B7+B8-B9-B10 -> 0 | C11: =C7+C8-C9-C10 -> 0 | D11: =D7+D8-D9-D10 -> 0 | E11: =E7+E8-E9-E10 -> 0 | F11: =F7+F8-F9-F10 -> 0 | G11: =G7+G8-G9-G10 -> 0 | H11: =H7+H8-H9-H10 -> 0 | I11: =I7+I8-I9-I10 -> 0 | ... K11: =K7+K8-K9-K10 -> 0 | L11: =IFERROR(IF(AND(L7<>"",L8<>"",L10<>""),L7+L8-L9-L10,IFERROR(L23*'1.IS'!L3,0)),"") -> 0 | M11: =IFERROR(IF(AND(M7<>"",M8<>"",M10<>""),M7+M8-M9-M10,IFERROR(M23*'1.IS'!M3,0)),"") -> 0 | N11: =IFERROR(IF(AND(N7<>"",N8<>"",N10<>""),N7+N8-N9-N10,IFERROR(N23*'1.IS'!N3,0)),"") -> 0 | O11: =IFERROR(IF(AND(O7<>"",O8<>"",O10<>""),O7+O8-O9-O10,IFERROR(O23*'1.IS'!O3,0)),"") -> 0 | P11: =IFERROR(IF(AND(P7<>"",P8<>"",P10<>""),P7+P8-P9-P10,IFERROR(P23*'1.IS'!P3,0)),"") -> 0
A12: (-) Variación de Working Capital - CWC | C12: =IF(B9>0,C11-B11,0) -> 0 | D12: =IF(C9>0,D11-C11,0) -> 0 | E12: =IF(D9>0,E11-D11,0) -> 0 | F12: =IF(E9>0,F11-E11,0) -> 0 | G12: =IF(F9>0,G11-F11,0) -> 0 | H12: =IF(G9>0,H11-G11,0) -> 0 | I12: =IF(H9>0,I11-H11,0) -> 0 | J12: =IF(I9>0,J11-I11,0) -> 0 | K12: =IF(J9>0,K11-J11,0) -> 0 | L12: =IF(VALUE(L11)=0,0,L11-K11) -> 0 | M12: =M11-L11 -> 0 | N12: =N11-M11 -> 0 | O12: =O11-N11 -> 0 | P12: =P11-O11 -> 0
A13: (-) Otros ajustes - Opcional; p.ej. Minority Interests | B13: ='1.IS'!B19 -> 0 | C13: ='1.IS'!C19 -> 0 | D13: ='1.IS'!D19 -> 0 | E13: ='1.IS'!E19 -> 0 | F13: ='1.IS'!F19 -> 0 | G13: ='1.IS'!G19 -> 0 | H13: ='1.IS'!H19 -> 0 | I13: ='1.IS'!I19 -> 0 | ... P13: ='1.IS'!P19
A14: Free Cash Flow | B14: =B3+B4+B5+B6-B12+B13 -> 0 | C14: =C3+C4+C5+C6-C12+C13 -> 0 | D14: =D3+D4+D5+D6-D12+D13 -> 0 | E14: =E3+E4+E5+E6-E12+E13 -> 0 | F14: =F3+F4+F5+F6-F12+F13 -> 0 | G14: =G3+G4+G5+G6-G12+G13 -> 0 | H14: =H3+H4+H5+H6-H12+H13 -> 0 | I14: =I3+I4+I5+I6-I12+I13 -> 0 | ... K14: =K3+K4+K5+K6-K12+K13 -> 0 | L14: =IFERROR(L3+L4+L5+L6-L12+L13,"") | M14: =IFERROR(M3+M4+M5+M6-M12+M13,"") | N14: =IFERROR(N3+N4+N5+N6-N12+N13,"") | O14: =IFERROR(O3+O4+O5+O6-O12+O13,"") | P14: =IFERROR(P3+P4+P5+P6-P12+P13,"")
A15: FCF Margin % | B15: =IFERROR(B14/'1.IS'!B3,"") | C15: =IFERROR(C14/'1.IS'!C3,"") | D15: =IFERROR(D14/'1.IS'!D3,"") | E15: =IFERROR(E14/'1.IS'!E3,"") | F15: =IFERROR(F14/'1.IS'!F3,"") | G15: =IFERROR(G14/'1.IS'!G3,"") | H15: =IFERROR(H14/'1.IS'!H3,"") | I15: =IFERROR(I14/'1.IS'!I3,"") | ... P15: =IFERROR(P14/'1.IS'!P3,"")
A16: Y/Y Growth % | C16: =IFERROR((C14-B14)/ABS(B14),"") | D16: =IFERROR((D14-C14)/ABS(C14),"") | E16: =IFERROR((E14-D14)/ABS(D14),"") | F16: =IFERROR((F14-E14)/ABS(E14),"") | G16: =IFERROR((G14-F14)/ABS(F14),"") | H16: =IFERROR((H14-G14)/ABS(G14),"") | I16: =IFERROR((I14-H14)/ABS(H14),"") | J16: =IFERROR((J14-I14)/ABS(I14),"") | K16: =IFERROR((K14-J14)/ABS(J14),"") | L16: =IFERROR((L14-K14)/K14,"") | M16: =IFERROR((M14-L14)/L14,"") | N16: =IFERROR((N14-M14)/M14,"") | O16: =IFERROR((O14-N14)/N14,"") | P16: =IFERROR((P14-O14)/O14,"")
A17: Free Cash Flow per share - FCFPS | B17: =IFERROR(B14/'1.IS'!B25,"") | C17: =IFERROR(C14/'1.IS'!C25,"") | D17: =IFERROR(D14/'1.IS'!D25,"") | E17: =IFERROR(E14/'1.IS'!E25,"") | F17: =IFERROR(F14/'1.IS'!F25,"") | G17: =IFERROR(G14/'1.IS'!G25,"") | H17: =IFERROR(H14/'1.IS'!H25,"") | I17: =IFERROR(I14/'1.IS'!I25,"") | ... P17: =IFERROR(P14/'1.IS'!P25,"") | Q17: AJUSTAR MANUALMENTE
A18: Y/Y Growth % | C18: =IFERROR((C17-B17)/ABS(B17),"") | D18: =IFERROR((D17-C17)/ABS(C17),"") | E18: =IFERROR((E17-D17)/ABS(D17),"") | F18: =IFERROR((F17-E17)/ABS(E17),"") | G18: =IFERROR((G17-F17)/ABS(F17),"") | H18: =IFERROR((H17-G17)/ABS(G17),"") | I18: =IFERROR((I17-H17)/ABS(H17),"") | J18: =IFERROR((J17-I17)/ABS(I17),"") | K18: =IFERROR((K17-J17)/ABS(J17),"") | L18: =IFERROR((L17-K17)/K17,"") | M18: =IFERROR((M17-L17)/L17,"") | N18: =IFERROR((N17-M17)/M17,"") | O18: =IFERROR((O17-N17)/N17,"") | P18: =IFERROR((P17-O17)/O17,"")
A19: Net Change in Cash | B19: =IFERROR(VLOOKUP("Net Change in Cash*",'9.TIKR_CF'!$A:$K,COLUMN(B19),FALSE),"0") -> 0 | C19: =IFERROR(VLOOKUP("Net Change in Cash*",'9.TIKR_CF'!$A:$K,COLUMN(C19),FALSE),"0") -> 0 | D19: =IFERROR(VLOOKUP("Net Change in Cash*",'9.TIKR_CF'!$A:$K,COLUMN(D19),FALSE),"0") -> 0 | E19: =IFERROR(VLOOKUP("Net Change in Cash*",'9.TIKR_CF'!$A:$K,COLUMN(E19),FALSE),"0") -> 0 | F19: =IFERROR(VLOOKUP("Net Change in Cash*",'9.TIKR_CF'!$A:$K,COLUMN(F19),FALSE),"0") -> 0 | G19: =IFERROR(VLOOKUP("Net Change in Cash*",'9.TIKR_CF'!$A:$K,COLUMN(G19),FALSE),"0") -> 0 | H19: =IFERROR(VLOOKUP("Net Change in Cash*",'9.TIKR_CF'!$A:$K,COLUMN(H19),FALSE),"0") -> 0 | I19: =IFERROR(VLOOKUP("Net Change in Cash*",'9.TIKR_CF'!$A:$K,COLUMN(I19),FALSE),"0") -> 0 | ... K19: =IFERROR(VLOOKUP("Net Change in Cash*",'9.TIKR_CF'!$A:$K,COLUMN(K19),FALSE),"0") -> 0 | L19: =IF('4.Valoracion'!L4>0,IFERROR('4.Valoracion'!L4-'4.Valoracion'!K4,0),IFERROR('4.Valoracion'!K4-'4.Valoracion'!L4,0)) -> 0 | M19: =IF('4.Valoracion'!M4>0,IFERROR('4.Valoracion'!M4-'4.Valoracion'!L4,0),IFERROR('4.Valoracion'!L4-'4.Valoracion'!M4,0)) -> 0 | N19: =IF('4.Valoracion'!N4>0,IFERROR('4.Valoracion'!N4-'4.Valoracion'!M4,0),IFERROR('4.Valoracion'!M4-'4.Valoracion'!N4,0)) -> 0 | O19: =IF('4.Valoracion'!O4>0,IFERROR('4.Valoracion'!O4-'4.Valoracion'!N4,0),IFERROR('4.Valoracion'!N4-'4.Valoracion'!O4,0)) -> 0 | P19: =IF('4.Valoracion'!P4>0,IFERROR('4.Valoracion'!P4-'4.Valoracion'!O4,0),IFERROR('4.Valoracion'!O4-'4.Valoracion'!P4,0)) -> 0
A21: Eficiencia y márgenes | B21: ='1.IS'!B$2 | C21: ='1.IS'!C$2 | D21: ='1.IS'!D$2 | E21: ='1.IS'!E$2 | F21: ='1.IS'!F$2 | G21: ='1.IS'!G$2 | H21: ='1.IS'!H$2 | I21: ='1.IS'!I$2 | ... P21: ='1.IS'!P$2 | Q21: {=IFERROR("Mediana "&CHAR(10)&INDEX(B2:K2,MATCH(TRUE,VALUE(B2:K2)>0,))&"-"&$K$2,"")}
A22: CapEx Mantenimiento / Ventas | B22: =IFERROR(ABS(B4)/'1.IS'!B$3,"") | C22: =IFERROR(ABS(C4)/'1.IS'!C$3,"") | D22: =IFERROR(ABS(D4)/'1.IS'!D$3,"") | E22: =IFERROR(ABS(E4)/'1.IS'!E$3,"") | F22: =IFERROR(ABS(F4)/'1.IS'!F$3,"") | G22: =IFERROR(ABS(G4)/'1.IS'!G$3,"") | H22: =IFERROR(ABS(H4)/'1.IS'!H$3,"") | I22: =IFERROR(ABS(I4)/'1.IS'!I$3,"") | ... K22: =IFERROR(ABS(K4)/'1.IS'!K$3,"") | L22: =IFERROR(ABS((K4*'1.IS'!L4)+'2.FCF'!K4)/'1.IS'!L$3,"") | M22: =$L$22 | N22: =$L$22 | O22: =$L$22 | P22: =$L$22 | Q22: =IFERROR(MEDIAN(B22:K22),"")
A23: Working Capital / Ventas | B23: =IFERROR(B11/'1.IS'!B$3,"") | C23: =IFERROR(C11/'1.IS'!C$3,"") | D23: =IFERROR(D11/'1.IS'!D$3,"") | E23: =IFERROR(E11/'1.IS'!E$3,"") | F23: =IFERROR(F11/'1.IS'!F$3,"") | G23: =IFERROR(G11/'1.IS'!G$3,"") | H23: =IFERROR(H11/'1.IS'!H$3,"") | I23: =IFERROR(I11/'1.IS'!I$3,"") | ... K23: =IFERROR(K11/'1.IS'!K$3,"") | L23: =IF(AND(VALUE(K7)=0,VALUE(K10)=0),0%,IFERROR(MEDIAN(I23:K23),Q23)) -> 0 | M23: =IFERROR($L$23,0%) -> 0 | N23: =IFERROR($L$23,0%) -> 0 | O23: =IFERROR($L$23,0%) -> 0 | P23: =IFERROR($L$23,0%) -> 0 | Q23: =IFERROR(MEDIAN(B23:K23),"")
A24: FCF / Ventas (FCF Margin) | B24: =IFERROR(B14/'1.IS'!B$3,"") | C24: =IFERROR(C14/'1.IS'!C$3,"") | D24: =IFERROR(D14/'1.IS'!D$3,"") | E24: =IFERROR(E14/'1.IS'!E$3,"") | F24: =IFERROR(F14/'1.IS'!F$3,"") | G24: =IFERROR(G14/'1.IS'!G$3,"") | H24: =IFERROR(H14/'1.IS'!H$3,"") | I24: =IFERROR(I14/'1.IS'!I$3,"") | ... P24: =IFERROR(P14/'1.IS'!P$3,"") | Q24: =IFERROR(MEDIAN(B24:K24),"")
A25: Conversión en Caja (EBITDA que se convierte en FCF) | B25: =IFERROR(B14/B3,"") | C25: =IFERROR(C14/C3,"") | D25: =IFERROR(D14/D3,"") | E25: =IFERROR(E14/E3,"") | F25: =IFERROR(F14/F3,"") | G25: =IFERROR(G14/G3,"") | H25: =IFERROR(H14/H3,"") | I25: =IFERROR(I14/I3,"") | ... P25: =IFERROR(P14/P3,"") | Q25: =IFERROR(MEDIAN(B25:K25),"")
A27: Asignación de capital (como % del FCF) | B27: ='1.IS'!B$2 | C27: ='1.IS'!C$2 | D27: ='1.IS'!D$2 | E27: ='1.IS'!E$2 | F27: ='1.IS'!F$2 | G27: ='1.IS'!G$2 | H27: ='1.IS'!H$2 | I27: ='1.IS'!I$2 | ... K27: ='1.IS'!K$2 | L27: {=IFERROR("Mediana "&CHAR(10)&INDEX(B2:K2,MATCH(TRUE,VALUE(B2:K2)>0,))&"-"&$K$2,"")}
A28: CapEx Expansión (crecimiento orgánico) | B28: =IF(B14>0,IFERROR(TIKR_Cálculos!B39/B$14,""),"-") -> - | C28: =IF(C14>0,IFERROR(TIKR_Cálculos!C39/C$14,""),"-") -> - | D28: =IF(D14>0,IFERROR(TIKR_Cálculos!D39/D$14,""),"-") -> - | E28: =IF(E14>0,IFERROR(TIKR_Cálculos!E39/E$14,""),"-") -> - | F28: =IF(F14>0,IFERROR(TIKR_Cálculos!F39/F$14,""),"-") -> - | G28: =IF(G14>0,IFERROR(TIKR_Cálculos!G39/G$14,""),"-") -> - | H28: =IF(H14>0,IFERROR(TIKR_Cálculos!H39/H$14,""),"-") -> - | I28: =IF(I14>0,IFERROR(TIKR_Cálculos!I39/I$14,""),"-") -> - | ... K28: =IF(K14>0,IFERROR(TIKR_Cálculos!K39/K$14,""),"-") -> - | L28: =IFERROR(MEDIAN(B28:K28),"")
A29: Adquisiciones (crecimiento inorgánico) | B29: =IF(B14>0,IFERROR(TIKR_Cálculos!B42/B$14,""),"-") -> - | C29: =IF(C14>0,IFERROR(TIKR_Cálculos!C42/C$14,""),"-") -> - | D29: =IF(D14>0,IFERROR(TIKR_Cálculos!D42/D$14,""),"-") -> - | E29: =IF(E14>0,IFERROR(TIKR_Cálculos!E42/E$14,""),"-") -> - | F29: =IF(F14>0,IFERROR(TIKR_Cálculos!F42/F$14,""),"-") -> - | G29: =IF(G14>0,IFERROR(TIKR_Cálculos!G42/G$14,""),"-") -> - | H29: =IF(H14>0,IFERROR(TIKR_Cálculos!H42/H$14,""),"-") -> - | I29: =IF(I14>0,IFERROR(TIKR_Cálculos!I42/I$14,""),"-") -> - | ... K29: =IF(K14>0,IFERROR(TIKR_Cálculos!K42/K$14,""),"-") -> - | L29: =IFERROR(MEDIAN(B29:K29),"")
A30: Dividendos | B30: =IF(B14>0,IFERROR(TIKR_Cálculos!B40/B$14,""),"-") -> - | C30: =IF(C14>0,IFERROR(TIKR_Cálculos!C40/C$14,""),"-") -> - | D30: =IF(D14>0,IFERROR(TIKR_Cálculos!D40/D$14,""),"-") -> - | E30: =IF(E14>0,IFERROR(TIKR_Cálculos!E40/E$14,""),"-") -> - | F30: =IF(F14>0,IFERROR(TIKR_Cálculos!F40/F$14,""),"-") -> - | G30: =IF(G14>0,IFERROR(TIKR_Cálculos!G40/G$14,""),"-") -> - | H30: =IF(H14>0,IFERROR(TIKR_Cálculos!H40/H$14,""),"-") -> - | I30: =IF(I14>0,IFERROR(TIKR_Cálculos!I40/I$14,""),"-") -> - | ... K30: =IF(K14>0,IFERROR(TIKR_Cálculos!K40/K$14,""),"-") -> - | L30: =IFERROR(MEDIAN(B30:K30),"")
A31: Recompras | B31: =IF(B14>0,IFERROR(TIKR_Cálculos!B41/B$14,""),"-") -> - | C31: =IF(C14>0,IFERROR(TIKR_Cálculos!C41/C$14,""),"-") -> - | D31: =IF(D14>0,IFERROR(TIKR_Cálculos!D41/D$14,""),"-") -> - | E31: =IF(E14>0,IFERROR(TIKR_Cálculos!E41/E$14,""),"-") -> - | F31: =IF(F14>0,IFERROR(TIKR_Cálculos!F41/F$14,""),"-") -> - | G31: =IF(G14>0,IFERROR(TIKR_Cálculos!G41/G$14,""),"-") -> - | H31: =IF(H14>0,IFERROR(TIKR_Cálculos!H41/H$14,""),"-") -> - | I31: =IF(I14>0,IFERROR(TIKR_Cálculos!I41/I$14,""),"-") -> - | ... K31: =IF(K14>0,IFERROR(TIKR_Cálculos!K41/K$14,""),"-") -> - | L31: =IFERROR(MEDIAN(B31:K31),"")
A32: Amortización neta de deuda | B32: =IF(B14>0,IFERROR(IF(TIKR_Cálculos!B43>0,TIKR_Cálculos!B43,0)/B14,""),"-") -> - | C32: =IF(C14>0,IFERROR(IF(TIKR_Cálculos!C43>0,TIKR_Cálculos!C43,0)/C14,""),"-") -> - | D32: =IF(D14>0,IFERROR(IF(TIKR_Cálculos!D43>0,TIKR_Cálculos!D43,0)/D14,""),"-") -> - | E32: =IF(E14>0,IFERROR(IF(TIKR_Cálculos!E43>0,TIKR_Cálculos!E43,0)/E14,""),"-") -> - | F32: =IF(F14>0,IFERROR(IF(TIKR_Cálculos!F43>0,TIKR_Cálculos!F43,0)/F14,""),"-") -> - | G32: =IF(G14>0,IFERROR(IF(TIKR_Cálculos!G43>0,TIKR_Cálculos!G43,0)/G14,""),"-") -> - | H32: =IF(H14>0,IFERROR(IF(TIKR_Cálculos!H43>0,TIKR_Cálculos!H43,0)/H14,""),"-") -> - | I32: =IF(I14>0,IFERROR(IF(TIKR_Cálculos!I43>0,TIKR_Cálculos!I43,0)/I14,""),"-") -> - | ... K32: =IF(K14>0,IFERROR(IF(TIKR_Cálculos!K43>0,TIKR_Cálculos!K43,0)/K14,""),"-") -> - | L32: =IFERROR(MEDIAN(B32:K32),"")
A33: Total | B33: =SUM(B28:B32) -> 0 | C33: =SUM(C28:C32) -> 0 | D33: =SUM(D28:D32) -> 0 | E33: =SUM(E28:E32) -> 0 | F33: =SUM(F28:F32) -> 0 | G33: =SUM(G28:G32) -> 0 | H33: =SUM(H28:H32) -> 0 | I33: =SUM(I28:I32) -> 0 | ... L33: =SUM(L28:L32) -> 0

Sheet 3.ROIC
A1: =IF('1.IS'!A1<>"",'1.IS'!A1,"") | B1: Retornos sobre el capital invertido | O1: #VALUE!
A2: (millones) | B2: ='1.IS'!B$2 | C2: ='1.IS'!C$2 | D2: ='1.IS'!D$2 | E2: ='1.IS'!E$2 | F2: ='1.IS'!F$2 | G2: ='1.IS'!G$2 | H2: ='1.IS'!H$2 | I2: ='1.IS'!I$2 | ... P2: ='1.IS'!P$2
A3: EBIT x (1-t) | B3: =IFERROR('1.IS'!B9*(1-'1.IS'!B17),"") | C3: =IFERROR('1.IS'!C9*(1-'1.IS'!C17),"") | D3: =IFERROR('1.IS'!D9*(1-'1.IS'!D17),"") | E3: =IFERROR('1.IS'!E9*(1-'1.IS'!E17),"") | F3: =IFERROR('1.IS'!F9*(1-'1.IS'!F17),"") | G3: =IFERROR('1.IS'!G9*(1-'1.IS'!G17),"") | H3: =IFERROR('1.IS'!H9*(1-'1.IS'!H17),"") | I3: =IFERROR('1.IS'!I9*(1-'1.IS'!I17),"") | ... P3: =IFERROR('1.IS'!P9*(1-'1.IS'!P17),"")
A4: Cash and cash equivalents | B4: =IFERROR(VLOOKUP("Cash And Equivalents*",'8.TIKR_BS'!$A:$K,COLUMN(B4),FALSE),"0") -> 0 | C4: =IFERROR(VLOOKUP("Cash And Equivalents*",'8.TIKR_BS'!$A:$K,COLUMN(C4),FALSE),"0") -> 0 | D4: =IFERROR(VLOOKUP("Cash And Equivalents*",'8.TIKR_BS'!$A:$K,COLUMN(D4),FALSE),"0") -> 0 | E4: =IFERROR(VLOOKUP("Cash And Equivalents*",'8.TIKR_BS'!$A:$K,COLUMN(E4),FALSE),"0") -> 0 | F4: =IFERROR(VLOOKUP("Cash And Equivalents*",'8.TIKR_BS'!$A:$K,COLUMN(F4),FALSE),"0") -> 0 | G4: =IFERROR(VLOOKUP("Cash And Equivalents*",'8.TIKR_BS'!$A:$K,COLUMN(G4),FALSE),"0") -> 0 | H4: =IFERROR(VLOOKUP("Cash And Equivalents*",'8.TIKR_BS'!$A:$K,COLUMN(H4),FALSE),"0") -> 0 | I4: =IFERROR(VLOOKUP("Cash And Equivalents*",'8.TIKR_BS'!$A:$K,COLUMN(I4),FALSE),"0") -> 0 | ... K4: =IFERROR(VLOOKUP("Cash And Equivalents*",'8.TIKR_BS'!$A:$K,COLUMN(K4),FALSE),"0") -> 0 | L4: =IFERROR(TIKR_Cálculos!C32,0) -> 0 | M4: =IFERROR(TIKR_Cálculos!D32,0) -> 0 | N4: =IFERROR(TIKR_Cálculos!E32,0) -> 0 | O4: =IFERROR(TIKR_Cálculos!F32,0) -> 0 | P4: =IFERROR(TIKR_Cálculos!G32,0) -> 0
A5: (-) Marketable Securities | B5: =IFERROR(VLOOKUP("Total Cash And Short Term Investments*",'8.TIKR_BS'!$A:$K,COLUMN(B5),FALSE)-B4,"0") -> 0 | C5: =IFERROR(VLOOKUP("Total Cash And Short Term Investments*",'8.TIKR_BS'!$A:$K,COLUMN(C5),FALSE)-C4,"0") -> 0 | D5: =IFERROR(VLOOKUP("Total Cash And Short Term Investments*",'8.TIKR_BS'!$A:$K,COLUMN(D5),FALSE)-D4,"0") -> 0 | E5: =IFERROR(VLOOKUP("Total Cash And Short Term Investments*",'8.TIKR_BS'!$A:$K,COLUMN(E5),FALSE)-E4,"0") -> 0 | F5: =IFERROR(VLOOKUP("Total Cash And Short Term Investments*",'8.TIKR_BS'!$A:$K,COLUMN(F5),FALSE)-F4,"0") -> 0 | G5: =IFERROR(VLOOKUP("Total Cash And Short Term Investments*",'8.TIKR_BS'!$A:$K,COLUMN(G5),FALSE)-G4,"0") -> 0 | H5: =IFERROR(VLOOKUP("Total Cash And Short Term Investments*",'8.TIKR_BS'!$A:$K,COLUMN(H5),FALSE)-H4,"0") -> 0 | I5: =IFERROR(VLOOKUP("Total Cash And Short Term Investments*",'8.TIKR_BS'!$A:$K,COLUMN(I5),FALSE)-I4,"0") -> 0 | ... K5: =IFERROR(VLOOKUP("Total Cash And Short Term Investments*",'8.TIKR_BS'!$A:$K,COLUMN(K5),FALSE)-K4,"0") -> 0 | L5: =IFERROR(TIKR_Cálculos!C33,0) -> 0 | M5: =IFERROR(TIKR_Cálculos!D33,0) -> 0 | N5: =IFERROR(TIKR_Cálculos!E33,0) -> 0 | O5: =IFERROR(TIKR_Cálculos!F33,0) -> 0 | P5: =IFERROR(TIKR_Cálculos!G33,0) -> 0
A6: (+) Short-Term Debt | B6: =IFERROR(VLOOKUP("Short-term Borrowings*",'8.TIKR_BS'!$A:$K,COLUMN(B6),FALSE),"0")+IFERROR(VLOOKUP("Current Portion of Long-Term Debt*",'8.TIKR_BS'!$A:$K,COLUMN(B6),FALSE),"0")+IFERROR(VLOOKUP("Finance Division Debt Current*",'8.TIKR_BS'!$A:$K,COLUMN(B6),FALSE),"0") -> 0 | C6: =IFERROR(VLOOKUP("Short-term Borrowings*",'8.TIKR_BS'!$A:$K,COLUMN(C6),FALSE),"0")+IFERROR(VLOOKUP("Current Portion of Long-Term Debt*",'8.TIKR_BS'!$A:$K,COLUMN(C6),FALSE),"0")+IFERROR(VLOOKUP("Finance Division Debt Current*",'8.TIKR_BS'!$A:$K,COLUMN(C6),FALSE),"0") -> 0 | D6: =IFERROR(VLOOKUP("Short-term Borrowings*",'8.TIKR_BS'!$A:$K,COLUMN(D6),FALSE),"0")+IFERROR(VLOOKUP("Current Portion of Long-Term Debt*",'8.TIKR_BS'!$A:$K,COLUMN(D6),FALSE),"0")+IFERROR(VLOOKUP("Finance Division Debt Current*",'8.TIKR_BS'!$A:$K,COLUMN(D6),FALSE),"0") -> 0 | E6: =IFERROR(VLOOKUP("Short-term Borrowings*",'8.TIKR_BS'!$A:$K,COLUMN(E6),FALSE),"0")+IFERROR(VLOOKUP("Current Portion of Long-Term Debt*",'8.TIKR_BS'!$A:$K,COLUMN(E6),FALSE),"0")+IFERROR(VLOOKUP("Finance Division Debt Current*",'8.TIKR_BS'!$A:$K,COLUMN(E6),FALSE),"0") -> 0 | F6: =IFERROR(VLOOKUP("Short-term Borrowings*",'8.TIKR_BS'!$A:$K,COLUMN(F6),FALSE),"0")+IFERROR(VLOOKUP("Current Portion of Long-Term Debt*",'8.TIKR_BS'!$A:$K,COLUMN(F6),FALSE),"0")+IFERROR(VLOOKUP("Finance Division Debt Current*",'8.TIKR_BS'!$A:$K,COLUMN(F6),FALSE),"0") -> 0 | G6: =IFERROR(VLOOKUP("Short-term Borrowings*",'8.TIKR_BS'!$A:$K,COLUMN(G6),FALSE),"0")+IFERROR(VLOOKUP("Current Portion of Long-Term Debt*",'8.TIKR_BS'!$A:$K,COLUMN(G6),FALSE),"0")+IFERROR(VLOOKUP("Finance Division Debt Current*",'8.TIKR_BS'!$A:$K,COLUMN(G6),FALSE),"0") -> 0 | H6: =IFERROR(VLOOKUP("Short-term Borrowings*",'8.TIKR_BS'!$A:$K,COLUMN(H6),FALSE),"0")+IFERROR(VLOOKUP("Current Portion of Long-Term Debt*",'8.TIKR_BS'!$A:$K,COLUMN(H6),FALSE),"0")+IFERROR(VLOOKUP("Finance Division Debt Current*",'8.TIKR_BS'!$A:$K,COLUMN(H6),FALSE),"0") -> 0 | I6: =IFERROR(VLOOKUP("Short-term Borrowings*",'8.TIKR_BS'!$A:$K,COLUMN(I6),FALSE),"0")+IFERROR(VLOOKUP("Current Portion of Long-Term Debt*",'8.TIKR_BS'!$A:$K,COLUMN(I6),FALSE),"0")+IFERROR(VLOOKUP("Finance Division Debt Current*",'8.TIKR_BS'!$A:$K,COLUMN(I6),FALSE),"0") -> 0 | ... K6: =IFERROR(VLOOKUP("Short-term Borrowings*",'8.TIKR_BS'!$A:$K,COLUMN(K6),FALSE),"0")+IFERROR(VLOOKUP("Current Portion of Long-Term Debt*",'8.TIKR_BS'!$A:$K,COLUMN(K6),FALSE),"0")+IFERROR(VLOOKUP("Finance Division Debt Current*",'8.TIKR_BS'!$A:$K,COLUMN(K6),FALSE),"0") -> 0 | L6: =IFERROR(TIKR_Cálculos!C35,0) -> 0 | M6: =IFERROR(TIKR_Cálculos!D35,0) -> 0 | N6: =IFERROR(TIKR_Cálculos!E35,0) -> 0 | O6: =IFERROR(TIKR_Cálculos!F35,0) -> 0 | P6: =IFERROR(TIKR_Cálculos!G35,0) -> 0
A7: (+) Long-Term Debt | B7: =IFERROR(VLOOKUP("Long-term Borrowings*",'8.TIKR_BS'!$A:$K,COLUMN(B7),FALSE),"0")+IFERROR(VLOOKUP("Long-Term Debt*",'8.TIKR_BS'!$A:$K,COLUMN(B7),FALSE),"0")+IFERROR(VLOOKUP("Finance Division Debt Non Current*",'8.TIKR_BS'!$A:$K,COLUMN(B7),FALSE),"0") -> 0 | C7: =IFERROR(VLOOKUP("Long-term Borrowings*",'8.TIKR_BS'!$A:$K,COLUMN(C7),FALSE),"0")+IFERROR(VLOOKUP("Long-Term Debt*",'8.TIKR_BS'!$A:$K,COLUMN(C7),FALSE),"0")+IFERROR(VLOOKUP("Finance Division Debt Non Current*",'8.TIKR_BS'!$A:$K,COLUMN(C7),FALSE),"0") -> 0 | D7: =IFERROR(VLOOKUP("Long-term Borrowings*",'8.TIKR_BS'!$A:$K,COLUMN(D7),FALSE),"0")+IFERROR(VLOOKUP("Long-Term Debt*",'8.TIKR_BS'!$A:$K,COLUMN(D7),FALSE),"0")+IFERROR(VLOOKUP("Finance Division Debt Non Current*",'8.TIKR_BS'!$A:$K,COLUMN(D7),FALSE),"0") -> 0 | E7: =IFERROR(VLOOKUP("Long-term Borrowings*",'8.TIKR_BS'!$A:$K,COLUMN(E7),FALSE),"0")+IFERROR(VLOOKUP("Long-Term Debt*",'8.TIKR_BS'!$A:$K,COLUMN(E7),FALSE),"0")+IFERROR(VLOOKUP("Finance Division Debt Non Current*",'8.TIKR_BS'!$A:$K,COLUMN(E7),FALSE),"0") -> 0 | F7: =IFERROR(VLOOKUP("Long-term Borrowings*",'8.TIKR_BS'!$A:$K,COLUMN(F7),FALSE),"0")+IFERROR(VLOOKUP("Long-Term Debt*",'8.TIKR_BS'!$A:$K,COLUMN(F7),FALSE),"0")+IFERROR(VLOOKUP("Finance Division Debt Non Current*",'8.TIKR_BS'!$A:$K,COLUMN(F7),FALSE),"0") -> 0 | G7: =IFERROR(VLOOKUP("Long-term Borrowings*",'8.TIKR_BS'!$A:$K,COLUMN(G7),FALSE),"0")+IFERROR(VLOOKUP("Long-Term Debt*",'8.TIKR_BS'!$A:$K,COLUMN(G7),FALSE),"0")+IFERROR(VLOOKUP("Finance Division Debt Non Current*",'8.TIKR_BS'!$A:$K,COLUMN(G7),FALSE),"0") -> 0 | H7: =IFERROR(VLOOKUP("Long-term Borrowings*",'8.TIKR_BS'!$A:$K,COLUMN(H7),FALSE),"0")+IFERROR(VLOOKUP("Long-Term Debt*",'8.TIKR_BS'!$A:$K,COLUMN(H7),FALSE),"0")+IFERROR(VLOOKUP("Finance Division Debt Non Current*",'8.TIKR_BS'!$A:$K,COLUMN(H7),FALSE),"0") -> 0 | I7: =IFERROR(VLOOKUP("Long-term Borrowings*",'8.TIKR_BS'!$A:$K,COLUMN(I7),FALSE),"0")+IFERROR(VLOOKUP("Long-Term Debt*",'8.TIKR_BS'!$A:$K,COLUMN(I7),FALSE),"0")+IFERROR(VLOOKUP("Finance Division Debt Non Current*",'8.TIKR_BS'!$A:$K,COLUMN(I7),FALSE),"0") -> 0 | ... K7: =IFERROR(VLOOKUP("Long-term Borrowings*",'8.TIKR_BS'!$A:$K,COLUMN(K7),FALSE),"0")+IFERROR(VLOOKUP("Long-Term Debt*",'8.TIKR_BS'!$A:$K,COLUMN(K7),FALSE),"0")+IFERROR(VLOOKUP("Finance Division Debt Non Current*",'8.TIKR_BS'!$A:$K,COLUMN(K7),FALSE),"0") -> 0 | L7: =IFERROR(TIKR_Cálculos!C36,0) -> 0 | M7: =IFERROR(TIKR_Cálculos!D36,0) -> 0 | N7: =IFERROR(TIKR_Cálculos!E36,0) -> 0 | O7: =IFERROR(TIKR_Cálculos!F36,0) -> 0 | P7: =IFERROR(TIKR_Cálculos!G36,0) -> 0
A8: (+) Current Operating Leases Liabilities | B8: =IFERROR(VLOOKUP("Current Portion of Capital Lease Obligations*",'8.TIKR_BS'!$A:$K,COLUMN(B8),FALSE),"0") -> 0 | C8: =IFERROR(VLOOKUP("Current Portion of Capital Lease Obligations*",'8.TIKR_BS'!$A:$K,COLUMN(C8),FALSE),"0") -> 0 | D8: =IFERROR(VLOOKUP("Current Portion of Capital Lease Obligations*",'8.TIKR_BS'!$A:$K,COLUMN(D8),FALSE),"0") -> 0 | E8: =IFERROR(VLOOKUP("Current Portion of Capital Lease Obligations*",'8.TIKR_BS'!$A:$K,COLUMN(E8),FALSE),"0") -> 0 | F8: =IFERROR(VLOOKUP("Current Portion of Capital Lease Obligations*",'8.TIKR_BS'!$A:$K,COLUMN(F8),FALSE),"0") -> 0 | G8: =IFERROR(VLOOKUP("Current Portion of Capital Lease Obligations*",'8.TIKR_BS'!$A:$K,COLUMN(G8),FALSE),"0") -> 0 | H8: =IFERROR(VLOOKUP("Current Portion of Capital Lease Obligations*",'8.TIKR_BS'!$A:$K,COLUMN(H8),FALSE),"0") -> 0 | I8: =IFERROR(VLOOKUP("Current Portion of Capital Lease Obligations*",'8.TIKR_BS'!$A:$K,COLUMN(I8),FALSE),"0") -> 0 | ... K8: =IFERROR(VLOOKUP("Current Portion of Capital Lease Obligations*",'8.TIKR_BS'!$A:$K,COLUMN(K8),FALSE),"0") -> 0 | L8: =IFERROR(K8*'1.IS'!L4+K8,"") | M8: =IFERROR(L8*'1.IS'!M4+L8,"") | N8: =IFERROR(M8*'1.IS'!N4+M8,"") | O8: =IFERROR(N8*'1.IS'!O4+N8,"") | P8: =IFERROR(O8*'1.IS'!P4+O8,"")
A9: (+) Non-Current Operating Leases Liabilities | B9: =IFERROR(VLOOKUP("Capital Leases*",'8.TIKR_BS'!$A:$K,COLUMN(B9),FALSE),"0") -> 0 | C9: =IFERROR(VLOOKUP("Capital Leases*",'8.TIKR_BS'!$A:$K,COLUMN(C9),FALSE),"0") -> 0 | D9: =IFERROR(VLOOKUP("Capital Leases*",'8.TIKR_BS'!$A:$K,COLUMN(D9),FALSE),"0") -> 0 | E9: =IFERROR(VLOOKUP("Capital Leases*",'8.TIKR_BS'!$A:$K,COLUMN(E9),FALSE),"0") -> 0 | F9: =IFERROR(VLOOKUP("Capital Leases*",'8.TIKR_BS'!$A:$K,COLUMN(F9),FALSE),"0") -> 0 | G9: =IFERROR(VLOOKUP("Capital Leases*",'8.TIKR_BS'!$A:$K,COLUMN(G9),FALSE),"0") -> 0 | H9: =IFERROR(VLOOKUP("Capital Leases*",'8.TIKR_BS'!$A:$K,COLUMN(H9),FALSE),"0") -> 0 | I9: =IFERROR(VLOOKUP("Capital Leases*",'8.TIKR_BS'!$A:$K,COLUMN(I9),FALSE),"0") -> 0 | ... K9: =IFERROR(VLOOKUP("Capital Leases*",'8.TIKR_BS'!$A:$K,COLUMN(K9),FALSE),"0") -> 0 | L9: =IFERROR(K9*'1.IS'!L4+K9,"") | M9: =IFERROR(L9*'1.IS'!M4+L9,"") | N9: =IFERROR(M9*'1.IS'!N4+M9,"") | O9: =IFERROR(N9*'1.IS'!O4+N9,"") | P9: =IFERROR(O9*'1.IS'!P4+O9,"")
A10: (+) Equity | B10: =IFERROR(VLOOKUP("Total Equity*",'8.TIKR_BS'!$A:$K,COLUMN(B10),FALSE),"0") -> 0 | C10: =IFERROR(VLOOKUP("Total Equity*",'8.TIKR_BS'!$A:$K,COLUMN(C10),FALSE),"0") -> 0 | D10: =IFERROR(VLOOKUP("Total Equity*",'8.TIKR_BS'!$A:$K,COLUMN(D10),FALSE),"0") -> 0 | E10: =IFERROR(VLOOKUP("Total Equity*",'8.TIKR_BS'!$A:$K,COLUMN(E10),FALSE),"0") -> 0 | F10: =IFERROR(VLOOKUP("Total Equity*",'8.TIKR_BS'!$A:$K,COLUMN(F10),FALSE),"0") -> 0 | G10: =IFERROR(VLOOKUP("Total Equity*",'8.TIKR_BS'!$A:$K,COLUMN(G10),FALSE),"0") -> 0 | H10: =IFERROR(VLOOKUP("Total Equity*",'8.TIKR_BS'!$A:$K,COLUMN(H10),FALSE),"0") -> 0 | I10: =IFERROR(VLOOKUP("Total Equity*",'8.TIKR_BS'!$A:$K,COLUMN(I10),FALSE),"0") -> 0 | ... K10: =IFERROR(VLOOKUP("Total Equity*",'8.TIKR_BS'!$A:$K,COLUMN(K10),FALSE),"0") -> 0 | L10: =IFERROR(K10+'1.IS'!L20+'1.IS'!L26*'4.Valoracion'!L3-AVERAGE('2.FCF'!$J$30:$K$30)*'2.FCF'!L14,"") | M10: =IFERROR(L10+'1.IS'!M20+'1.IS'!M26*'4.Valoracion'!M3-AVERAGE('2.FCF'!$J$30:$K$30)*'2.FCF'!M14,"") | N10: =IFERROR(M10+'1.IS'!N20+'1.IS'!N26*'4.Valoracion'!N3-AVERAGE('2.FCF'!$J$30:$K$30)*'2.FCF'!N14,"") | O10: =IFERROR(N10+'1.IS'!O20+'1.IS'!O26*'4.Valoracion'!O3-AVERAGE('2.FCF'!$J$30:$K$30)*'2.FCF'!O14,"") | P10: =IFERROR(O10+'1.IS'!P20+'1.IS'!P26*'4.Valoracion'!P3-AVERAGE('2.FCF'!$J$30:$K$30)*'2.FCF'!P14,"")
A11: Invested Capital | B11: =B10+B6+B7+B8+B9-B5 -> 0 | C11: =C10+C6+C7+C8+C9-C5 -> 0 | D11: =D10+D6+D7+D8+D9-D5 -> 0 | E11: =E10+E6+E7+E8+E9-E5 -> 0 | F11: =F10+F6+F7+F8+F9-F5 -> 0 | G11: =G10+G6+G7+G8+G9-G5 -> 0 | H11: =H10+H6+H7+H8+H9-H5 -> 0 | I11: =I10+I6+I7+I8+I9-I5 -> 0 | ... K11: =K10+K6+K7+K8+K9-K5 -> 0 | L11: =IFERROR(L10+L6+L7+L8+L9-L5,"") | M11: =IFERROR(M10+M6+M7+M8+M9-M5,"") | N11: =IFERROR(N10+N6+N7+N8+N9-N5,"") | O11: =IFERROR(O10+O6+O7+O8+O9-O5,"") | P11: =IFERROR(P10+P6+P7+P8+P9-P5,"")
A13: Ratios de rentabilidad | B13: ='1.IS'!B$2 | C13: ='1.IS'!C$2 | D13: ='1.IS'!D$2 | E13: ='1.IS'!E$2 | F13: ='1.IS'!F$2 | G13: ='1.IS'!G$2 | H13: ='1.IS'!H$2 | I13: ='1.IS'!I$2 | ... P13: ='1.IS'!P$2 | Q13: {=IFERROR("Mediana "&CHAR(10)&INDEX(B2:K2,MATCH(TRUE,VALUE(B2:K2)>0,))&" - "&K$2,"")}
A14: ROE | B14: =IFERROR('1.IS'!B20/B10,"") | C14: =IFERROR('1.IS'!C20/C10,"") | D14: =IFERROR('1.IS'!D20/D10,"") | E14: =IFERROR('1.IS'!E20/E10,"") | F14: =IFERROR('1.IS'!F20/F10,"") | G14: =IFERROR('1.IS'!G20/G10,"") | H14: =IFERROR('1.IS'!H20/H10,"") | I14: =IFERROR('1.IS'!I20/I10,"") | ... P14: =IFERROR('1.IS'!P20/P10,"") | Q14: =IFERROR(MEDIAN(B14:K14),"")
A15: ROIC | B15: =IFERROR(B3/B11,"") | C15: =IFERROR(C3/C11,"") | D15: =IFERROR(D3/D11,"") | E15: =IFERROR(E3/E11,"") | F15: =IFERROR(F3/F11,"") | G15: =IFERROR(G3/G11,"") | H15: =IFERROR(H3/H11,"") | I15: =IFERROR(I3/I11,"") | ... P15: =IFERROR(P3/P11,"") | Q15: =IFERROR(MEDIAN(B15:K15),"")
A16: Tasa de reinversión | B16: =IF('2.FCF'!B14>0,IFERROR(TIKR_Cálculos!B12/'2.FCF'!B14,""),"") | C16: =IF('2.FCF'!C14>0,IFERROR(TIKR_Cálculos!C12/'2.FCF'!C14,""),"") | D16: =IF('2.FCF'!D14>0,IFERROR(TIKR_Cálculos!D12/'2.FCF'!D14,""),"") | E16: =IF('2.FCF'!E14>0,IFERROR(TIKR_Cálculos!E12/'2.FCF'!E14,""),"") | F16: =IF('2.FCF'!F14>0,IFERROR(TIKR_Cálculos!F12/'2.FCF'!F14,""),"") | G16: =IF('2.FCF'!G14>0,IFERROR(TIKR_Cálculos!G12/'2.FCF'!G14,""),"") | H16: =IF('2.FCF'!H14>0,IFERROR(TIKR_Cálculos!H12/'2.FCF'!H14,""),"") | I16: =IF('2.FCF'!I14>0,IFERROR(TIKR_Cálculos!I12/'2.FCF'!I14,""),"") | ... K16: =IF('2.FCF'!K14>0,IFERROR(TIKR_Cálculos!K12/'2.FCF'!K14,""),"") | L16: - | M16: - | N16: - | O16: - | P16: - | Q16: =IFERROR(MEDIAN(B16:K16),"")

Sheet 4.Valoracion
A1: =IF('1.IS'!A1<>"",'1.IS'!A1,"") | B1: Valoración | O1: #VALUE!
A2: Valoración (millones) | B2: ='1.IS'!B$2 | C2: ='1.IS'!C$2 | D2: ='1.IS'!D$2 | E2: ='1.IS'!E$2 | F2: ='1.IS'!F$2 | G2: ='1.IS'!G$2 | H2: ='1.IS'!H$2 | I2: ='1.IS'!I$2 | ... P2: ='1.IS'!P$2
A3: Market cap | B3: =IFERROR(VLOOKUP("Market Cap (MM)",'10.TIKR_Val'!$A:$K,COLUMN(B4),FALSE)*('1.IS'!B25/VLOOKUP("Weighted Average Basic Shares Outstanding*",'7.TIKR_IS'!$A:$K,COLUMN(B4),FALSE)),"") | C3: =IFERROR(VLOOKUP("Market Cap (MM)",'10.TIKR_Val'!$A:$K,COLUMN(C4),FALSE)*('1.IS'!C25/VLOOKUP("Weighted Average Basic Shares Outstanding*",'7.TIKR_IS'!$A:$K,COLUMN(C4),FALSE)),"") | D3: =IFERROR(VLOOKUP("Market Cap (MM)",'10.TIKR_Val'!$A:$K,COLUMN(D4),FALSE)*('1.IS'!D25/VLOOKUP("Weighted Average Basic Shares Outstanding*",'7.TIKR_IS'!$A:$K,COLUMN(D4),FALSE)),"") | E3: =IFERROR(VLOOKUP("Market Cap (MM)",'10.TIKR_Val'!$A:$K,COLUMN(E4),FALSE)*('1.IS'!E25/VLOOKUP("Weighted Average Basic Shares Outstanding*",'7.TIKR_IS'!$A:$K,COLUMN(E4),FALSE)),"") | F3: =IFERROR(VLOOKUP("Market Cap (MM)",'10.TIKR_Val'!$A:$K,COLUMN(F4),FALSE)*('1.IS'!F25/VLOOKUP("Weighted Average Basic Shares Outstanding*",'7.TIKR_IS'!$A:$K,COLUMN(F4),FALSE)),"") | G3: =IFERROR(VLOOKUP("Market Cap (MM)",'10.TIKR_Val'!$A:$K,COLUMN(G4),FALSE)*('1.IS'!G25/VLOOKUP("Weighted Average Basic Shares Outstanding*",'7.TIKR_IS'!$A:$K,COLUMN(G4),FALSE)),"") | H3: =IFERROR(VLOOKUP("Market Cap (MM)",'10.TIKR_Val'!$A:$K,COLUMN(H4),FALSE)*('1.IS'!H25/VLOOKUP("Weighted Average Basic Shares Outstanding*",'7.TIKR_IS'!$A:$K,COLUMN(H4),FALSE)),"") | I3: =IFERROR(VLOOKUP("Market Cap (MM)",'10.TIKR_Val'!$A:$K,COLUMN(I4),FALSE)*('1.IS'!I25/VLOOKUP("Weighted Average Basic Shares Outstanding*",'7.TIKR_IS'!$A:$K,COLUMN(I4),FALSE)),"") | ... K3: =IFERROR(VLOOKUP("Market Cap (MM)",'10.TIKR_Val'!$A:$K,COLUMN(K4),FALSE)*('1.IS'!K25/VLOOKUP("Weighted Average Basic Shares Outstanding*",'7.TIKR_IS'!$A:$K,COLUMN(K4),FALSE)),"") | L3: =IFERROR($B$19*'1.IS'!L25,"") | M3: =IFERROR($B$19*'1.IS'!M25,"") | N3: =IFERROR($B$19*'1.IS'!N25,"") | O3: =IFERROR($B$19*'1.IS'!O25,"") | P3: =IFERROR($B$19*'1.IS'!P25,"")
A4: Deuda Neta | B4: =('3.ROIC'!B7+'3.ROIC'!B6)-('3.ROIC'!B4+'3.ROIC'!B5) -> 0 | C4: =('3.ROIC'!C7+'3.ROIC'!C6)-('3.ROIC'!C4+'3.ROIC'!C5) -> 0 | D4: =('3.ROIC'!D7+'3.ROIC'!D6)-('3.ROIC'!D4+'3.ROIC'!D5) -> 0 | E4: =('3.ROIC'!E7+'3.ROIC'!E6)-('3.ROIC'!E4+'3.ROIC'!E5) -> 0 | F4: =('3.ROIC'!F7+'3.ROIC'!F6)-('3.ROIC'!F4+'3.ROIC'!F5) -> 0 | G4: =('3.ROIC'!G7+'3.ROIC'!G6)-('3.ROIC'!G4+'3.ROIC'!G5) -> 0 | H4: =('3.ROIC'!H7+'3.ROIC'!H6)-('3.ROIC'!H4+'3.ROIC'!H5) -> 0 | I4: =('3.ROIC'!I7+'3.ROIC'!I6)-('3.ROIC'!I4+'3.ROIC'!I5) -> 0 | ... K4: =('3.ROIC'!K7+'3.ROIC'!K6)-('3.ROIC'!K4+'3.ROIC'!K5) -> 0 | L4: =IFERROR(L5*'1.IS'!L5,"") | M4: =IFERROR(M5*'1.IS'!M5,"") | N4: =IFERROR(N5*'1.IS'!N5,"") | O4: =IFERROR(O5*'1.IS'!O5,"") | P4: =IFERROR(P5*'1.IS'!P5,"") | R4: AJUSTAR MANUALMENTE
A5: Deuda neta / EBITDA | B5: =IFERROR('4.Valoracion'!B4/'1.IS'!B5,"") | C5: =IFERROR('4.Valoracion'!C4/'1.IS'!C5,"") | D5: =IFERROR('4.Valoracion'!D4/'1.IS'!D5,"") | E5: =IFERROR('4.Valoracion'!E4/'1.IS'!E5,"") | F5: =IFERROR('4.Valoracion'!F4/'1.IS'!F5,"") | G5: =IFERROR('4.Valoracion'!G4/'1.IS'!G5,"") | H5: =IFERROR('4.Valoracion'!H4/'1.IS'!H5,"") | I5: =IFERROR('4.Valoracion'!I4/'1.IS'!I5,"") | ... K5: =IFERROR('4.Valoracion'!K4/'1.IS'!K5,"") | L5: =IFERROR(_xlfn.FORECAST.LINEAR(2025, B5:K5, B2:K2),K5) | M5: =L5 | N5: =M5 | O5: =N5 | P5: =O5
A6: Enterprise Value (EV) | B6: =IFERROR(B3+B4,"") | C6: =IFERROR(C3+C4,"") | D6: =IFERROR(D3+D4,"") | E6: =IFERROR(E3+E4,"") | F6: =IFERROR(F3+F4,"") | G6: =IFERROR(G3+G4,"") | H6: =IFERROR(H3+H4,"") | I6: =IFERROR(I3+I4,"") | ... K6: =IFERROR(K3+K4,"") | L6: =IFERROR((L3+L4),"") | M6: =IFERROR((M3+M4),"") | N6: =IFERROR((N3+N4),"") | O6: =IFERROR((O3+O4),"") | P6: =IFERROR((P3+P4),"")
A7: EBITDA | B7: ='1.IS'!B5 -> 0 | C7: ='1.IS'!C5 -> 0 | D7: ='1.IS'!D5 -> 0 | E7: ='1.IS'!E5 -> 0 | F7: ='1.IS'!F5 -> 0 | G7: ='1.IS'!G5 -> 0 | H7: ='1.IS'!H5 -> 0 | I7: ='1.IS'!I5 -> 0 | ... P7: ='1.IS'!P5
A8: EBIT | B8: ='1.IS'!B9 -> 0 | C8: ='1.IS'!C9 -> 0 | D8: ='1.IS'!D9 -> 0 | E8: ='1.IS'!E9 -> 0 | F8: ='1.IS'!F9 -> 0 | G8: ='1.IS'!G9 -> 0 | H8: ='1.IS'!H9 -> 0 | I8: ='1.IS'!I9 -> 0 | ... P8: ='1.IS'!P9
A9: Net income | B9: ='1.IS'!B20 -> 0 | C9: ='1.IS'!C20 -> 0 | D9: ='1.IS'!D20 -> 0 | E9: ='1.IS'!E20 -> 0 | F9: ='1.IS'!F20 -> 0 | G9: ='1.IS'!G20 -> 0 | H9: ='1.IS'!H20 -> 0 | I9: ='1.IS'!I20 -> 0 | ... P9: ='1.IS'!P20
A10: FCF | B10: ='2.FCF'!B14 -> 0 | C10: ='2.FCF'!C14 -> 0 | D10: ='2.FCF'!D14 -> 0 | E10: ='2.FCF'!E14 -> 0 | F10: ='2.FCF'!F14 -> 0 | G10: ='2.FCF'!G14 -> 0 | H10: ='2.FCF'!H14 -> 0 | I10: ='2.FCF'!I14 -> 0 | ... P10: ='2.FCF'!P14
A12: Múltiplos de valoración (opcional) | B12: =B2 | C12: =C2 | D12: =D2 | E12: =E2 | F12: =F2 | G12: =G2 | H12: =H2 | I12: =I2 | ... P12: =P2 | Q12: {=IFERROR("Mediana "&CHAR(10)&INDEX(B2:K2,MATCH(TRUE,VALUE(B2:K2)>0,))&" - "&K$2,"")}
A13: PER | B13: =IFERROR(B3/B9,"") | C13: =IFERROR(C3/C9,"") | D13: =IFERROR(D3/D9,"") | E13: =IFERROR(E3/E9,"") | F13: =IFERROR(F3/F9,"") | G13: =IFERROR(G3/G9,"") | H13: =IFERROR(H3/H9,"") | I13: =IFERROR(I3/I9,"") | ... K13: =IFERROR(K3/K9,"") | L13: =IF($B$19<>"",IFERROR($B$19/'1.IS'!L23,""),"") | M13: =IF($B$19<>"",IFERROR($B$19/'1.IS'!M23,""),"") | N13: =IF($B$19<>"",IFERROR($B$19/'1.IS'!N23,""),"") | O13: =IF($B$19<>"",IFERROR($B$19/'1.IS'!O23,""),"") | P13: =IF($B$19<>"",IFERROR($B$19/'1.IS'!P23,""),"") | Q13: =IFERROR(MEDIAN(B13:K13),"")
A14: EV / FCF | B14: =IFERROR(B6/B10,"") | C14: =IFERROR(C6/C10,"") | D14: =IFERROR(D6/D10,"") | E14: =IFERROR(E6/E10,"") | F14: =IFERROR(F6/F10,"") | G14: =IFERROR(G6/G10,"") | H14: =IFERROR(H6/H10,"") | I14: =IFERROR(I6/I10,"") | ... K14: =IFERROR(K6/K10,"") | L14: =IF($B$19<>"",IFERROR(L6/L10,""),"") | M14: =IF($B$19<>"",IFERROR(M6/M10,""),"") | N14: =IF($B$19<>"",IFERROR(N6/N10,""),"") | O14: =IF($B$19<>"",IFERROR(O6/O10,""),"") | P14: =IF($B$19<>"",IFERROR(P6/P10,""),"") | Q14: =IFERROR(MEDIAN(B14:K14),"")
A15: Mediana EV / FCF | B15: =$Q$14 | C15: =$Q$14 | D15: =$Q$14 | E15: =$Q$14 | F15: =$Q$14 | G15: =$Q$14 | H15: =$Q$14 | I15: =$Q$14 | ... K15: =$Q$14
A16: EV / EBITDA | B16: =IFERROR(B6/B7,"") | C16: =IFERROR(C6/C7,"") | D16: =IFERROR(D6/D7,"") | E16: =IFERROR(E6/E7,"") | F16: =IFERROR(F6/F7,"") | G16: =IFERROR(G6/G7,"") | H16: =IFERROR(H6/H7,"") | I16: =IFERROR(I6/I7,"") | ... K16: =IFERROR(K6/K7,"") | L16: =IF($B$19<>"",IFERROR(L6/L7,""),"") | M16: =IF($B$19<>"",IFERROR(M6/M7,""),"") | N16: =IF($B$19<>"",IFERROR(N6/N7,""),"") | O16: =IF($B$19<>"",IFERROR(O6/O7,""),"") | P16: =IF($B$19<>"",IFERROR(P6/P7,""),"") | Q16: =IFERROR(MEDIAN(B16:K16),"")
A17: EV / EBIT | B17: =IFERROR(B6/B8,"") | C17: =IFERROR(C6/C8,"") | D17: =IFERROR(D6/D8,"") | E17: =IFERROR(E6/E8,"") | F17: =IFERROR(F6/F8,"") | G17: =IFERROR(G6/G8,"") | H17: =IFERROR(H6/H8,"") | I17: =IFERROR(I6/I8,"") | ... K17: =IFERROR(K6/K8,"") | L17: =IF($B$19<>"",IFERROR(L6/L8,""),"") | M17: =IF($B$19<>"",IFERROR(M6/M8,""),"") | N17: =IF($B$19<>"",IFERROR(N6/N8,""),"") | O17: =IF($B$19<>"",IFERROR(O6/O8,""),"") | P17: =IF($B$19<>"",IFERROR(P6/P8,""),"") | Q17: =IFERROR(MEDIAN(B17:K17),"")
A19: Precio por acción actual
A21: Múltiplos de valoración | B21: Objetivo
A22: PER | B22: =L13
A23: EV / FCF | B23: =L14 | E23: AJUSTAR MANUALMENTE
A24: EV / EBITDA | B24: =L16
A25: EV / EBIT | B25: =L17
